Workbook

Sheet 1-2024
B2: EGRESOS | L2: INFORMACION RELEVANTE | O2: BIOMETRIAS
B3: Fecha | C3: Descripcion | D3: Piezas | E3: Precio Unitario | F3: Precio Total | G3: Proveedor | H3: Compro | I3: Tipo de Gasto | J3: Observacion | L3: No. de Ciclo | M3: 1-2024 | O3: Fecha | P3: Promedio de Peso [Gr.]
B4: 45707 | C4: Malla hexagonal galvanizada 15 mts | D4: 1 | E4: 450 | F4: =D4*E4 -> 450 | G4: AGROTROPIC | H4: Juan Carlos | I4: Infraestructura | L4: Fecha de Ingreso | M4: 27/03/2024 | O4: 45378 | P4: 0.1
B5: 45717 | C5: Daimetoprim | D5: 1 | E5: 22 | F5: =D5*E5 -> 22 | G5: AGROTROPIC | H5: Juan Carlos | I5: Produccion | L5: No. de Organismos | M5: 70 | O5: 45414 | P5: 26
B6: 45720 | C6: Bulto de Alimento para Pollo Iniciador 40 Kg (Dividido 20 Kg) | D6: 1 | E6: 218.555 | F6: =D6*E6 -> 218.555 | G6: CAMPIBAR | H6: Juan Carlos | I6: Produccion | L6: Costo de compra por Organismo | M6: 1 | O6: 45423 | P6: 40
B7: 45726 | C7: Bulto de Alimento para Pollo Iniciador 40 Kg | D7: 1 | E7: 438 | F7: =D7*E7 -> 438 | G7: JYY AGROPECUARIA | H7: Juan Carlos | I7: Produccion | L7: Costo de Produccion Total | M7: =F28 -> 224.5 | O7: 45451 | P7: 71
B8: 45728 | C8: Malla hexagonal galvanizada 15 mts (Dividido) | D8: 1 | E8: 225 | F8: =D8*E8 -> 225 | G8: AGROTROPIC | H8: Juan Carlos | I8: Infraestructura | L8: Costo de Produccion por Organismo | M8: =F28/M10 -> 3.2071429 | O8: 45467 | P8: 110
B9: 45728 | D9: 1 | E9: 265 | F9: =D9*E9 -> 265 | G9: AGROTROPIC | H9: Juan Carlos | I9: Produccion | L9: Mortandad | O9: 45482 | P9: 126.4
B10: 45735 | C10: Bulto de Alimento para Pollo Iniciador 40 Kg | D10: 1 | E10: 440 | F10: =D10*E10 -> 440 | G10: JYY AGROPECUARIA | H10: Juan Carlos | I10: Produccion | L10: Organismos Aprovechados | M10: =M5-M9 -> 70 | O10: 45500 | P10: 166
B11: 45741 | C11: Bulto de Alimento para Pollo Desarrollo 40 Kg | D11: 1 | E11: 357 | F11: =D11*E11 -> 357 | G11: CENTRAL DE ABASTOS | H11: Juan Carlos | I11: Produccion | L11: Participacion por Organismo | M11: =100/M5 -> 1.4285714 | O11: 45516 | P11: 233
B12: 45747 | C12: Bulto de Alimento para Pollo Engorda 40 Kg | D12: 2 | E12: 449 | F12: =D12*E12 -> 898 | G12: JYY AGROPECUARIA | H12: Juan Carlos | I12: Produccion | L12: Organismos Vendidos | M12: 64 | O12: 45531 | P12: 271
B13: 45747 | C13: Lona Azul 5x7 mts (Dividido) | D13: 0.5 | E13: 448.33 | F13: =D13*E13 -> 224.165 | G13: Vaqueiros Ferreteros | H13: Juan Carlos | I13: Infraestructura | L13: Organismos Restantes | M13: =M10-M12 -> 6 | O13: 45545 | P13: 327
B14: 45750 | C14: Bebedero Automatico | D14: 1 | E14: 378.63 | F14: =D14*E14 -> 378.63 | G14: Mercado Libre | H14: Juan Carlos | I14: Infraestructura | L14: Biomasa Vendida | M14: 217.25 | O14: 45560 | P14: 400
B15: 45750 | C15: Manguera para bebedero | D15: 1 | E15: 35 | F15: =D15*E15 -> 35 | G15: Vaqueiros Ferreteros | H15: Juan Carlos | I15: Produccion | L15: Promedio de Peso | M15: =M14/M12 -> 3.3945313 | O15: 45575 | P15: 463
B16: 45754 | C16: Bulto de Alimento para Pollo Engorda 40 Kg | D16: 2 | E16: 449 | F16: =D16*E16 -> 898 | G16: JYY AGROPECUARIA | H16: Juan Carlos | I16: Infraestructura | L16: Fecha de Ultima Venta | M16: 03/05/2025 | O16: 45590 | P16: 507
B17: 45754 | C17: Esparrago para bebedero | D17: 1 | E17: 45.335 | F17: =D17*E17 -> 45.335 | G17: Vaqueiros Ferreteros | H17: Juan Carlos | I17: Infraestructura | L17: Dias Transcurridos del Ciclo | M17: =M16-M4 -> 402 | O17: 45612 | P17: 693
B18: 45769 | C18: Bulto de Maiz Blanco Entero 25 Kg | D18: 2 | E18: 200 | F18: =D18*E18 -> 400 | G18: JYY AGROPECUARIA | H18: Juan Carlos | I18: Produccion | O18: 45636 | P18: 360
B19: 45769 | C19: Bulto de Alimento para Pollo Engorda 40 Kg | D19: 1.5 | E19: 449 | F19: =D19*E19 -> 673.5 | G19: JYY AGROPECUARIA | H19: Juan Carlos | I19: Produccion | O19: 45652 | P19: 380
B20: 45770 | C20: Bolsas Plasticas Transparentes | D20: 0.5 | E20: 57.884 | F20: =D20*E20 -> 28.942 | G20: CENTRAL DE ABASTOS | H20: Juan Carlos | I20: Produccion | O20: 45677 | P20: 266
B21: 45770 | C21: Bolsas Plasticas de Asa | D21: 0.5 | E21: 42.0848 | F21: =D21*E21 -> 21.0424 | G21: CENTRAL DE ABASTOS | H21: Juan Carlos | I21: Produccion | O21: 45695 | P21: 350
B22: 45778 | C22: Comedero Tolva | D22: 1 | E22: 160 | F22: =D22*E22 -> 160 | G22: AGROTROPIC | H22: Juan Carlos | I22: Infraestructura
B23: 45779 | C23: Bulto de Alimento para Pollo Engorda 40 Kg | D23: 2 | E23: 449 | F23: =D23*E23 -> 898 | G23: JYY AGROPECUARIA | H23: Juan Carlos | I23: Produccion
B24: 45779 | C24: Bulto de Maiz Blanco Entero 25 Kg | D24: 1 | E24: 200 | F24: =D24*E24 -> 200 | G24: JYY AGROPECUARIA | H24: Juan Carlos | I24: Produccion
B25: 45790 | C25: Bulto de Alimento para Pollo Engorda 40 Kg | D25: 1 | E25: 449 | F25: =D25*E25 -> 449 | G25: JYY AGROPECUARIA | H25: Juan Carlos | I25: Produccion
B26: 45790 | C26: Bulto de Maiz Blanco Entero 25 Kg | D26: 1 | E26: 205 | F26: =D26*E26 -> 205 | G26: JYY AGROPECUARIA | H26: Juan Carlos | I26: Produccion
B27: 45797 | C27: Materiales Varios | D27: 0.5 | E27: 333.23 | F27: =D27*E27 -> 166.615 | G27: Vaqueiros Ferreteros | H27: Juan Carlos | I27: Infraestructura
B28: 45803 | C28: Bulto de Alimento para Pollo Engorda 40 Kg | D28: 0.5 | E28: 449 | F28: =D28*E28 -> 224.5 | G28: JYY AGROPECUARIA | H28: Juan Carlos | I28: Produccion
F29: =SUM(F4:F28) -> 8321.2844
B31: INFORMACION DE PARTICIPANTES
B32: Animales Iniciales | C32: Participantes | D32: Participacion [%] | E32: Animales Restantes | F32: Gasto | G32: Ingreso | H32: Pago | I32: Restante
B33: 10 | C33: Juan Carlos Jimenez Ara | D33: =(B33*$M$5)/100 -> 7 | E33: =$M$7*D33 -> 1571.5 | F33: 61391.211 | G33: 136860.5 | H33: =G33 -> 136860.5 | I33: =F33-H33 -> -75469.289
E34: =SUBTOTAL(109,Table8[Animales Restantes]) -> 1571.5 | F34: =SUBTOTAL(109,Table8[Gasto]) -> 61391.211 | G34: =SUBTOTAL(109,Table8[Ingreso]) -> 136860.5 | H34: =SUBTOTAL(109,Table8[Pago]) -> 136860.5 | I34: =SUBTOTAL(109,Table8[Restante]) -> -75469.289
B36: VENTAS
B37: Fecha | C37: Cliente | D37: Precio por Kg | E37: Peso del Organismo | F37: Precio del Organismo | G37: Pendiente | H37: Pago | I37: Observaciones | J37: Metodo de Pago
B38: 45849 | C38: Manlio Fab io Aguilar Marin | D38: 95 | E38: 3.6 | F38: =Table914[[#This Row],[Precio por Kg]]*Table914[[#This Row],[Peso del Organismo]] -> 342 | G38: 0 | H38: =Table914[[#This Row],[Precio del Organismo]]-Table914[[#This Row],[Pendiente]] -> 342 | J38: Transferencia
B39: 45849 | C39: Manlio Fab io Aguilar Marin | D39: 95 | E39: 3 | F39: =Table914[[#This Row],[Precio por Kg]]*Table914[[#This Row],[Peso del Organismo]] -> 285 | G39: 0 | H39: =Table914[[#This Row],[Precio del Organismo]]-Table914[[#This Row],[Pendiente]] -> 285 | J39: Transferencia
B40: 45849 | C40: Manlio Fab io Aguilar Marin | D40: 94.594595 | E40: 3.7 | F40: =Table914[[#This Row],[Precio por Kg]]*Table914[[#This Row],[Peso del Organismo]] -> 350 | G40: 0 | H40: =Table914[[#This Row],[Precio del Organismo]]-Table914[[#This Row],[Pendiente]] -> 350 | J40: Transferencia
B41: 45849 | C41: Manlio Fab io Aguilar Marin | D41: 94.594595 | E41: 3.7 | F41: =Table914[[#This Row],[Precio por Kg]]*Table914[[#This Row],[Peso del Organismo]] -> 350 | G41: 0 | H41: =Table914[[#This Row],[Precio del Organismo]]-Table914[[#This Row],[Pendiente]] -> 350 | J41: Transferencia
B42: 45849 | C42: Manlio Fab io Aguilar Marin | D42: 95 | E42: 3.8 | F42: =Table914[[#This Row],[Precio por Kg]]*Table914[[#This Row],[Peso del Organismo]] -> 361 | G42: 0 | H42: =Table914[[#This Row],[Precio del Organismo]]-Table914[[#This Row],[Pendiente]] -> 361 | J42: Transferencia
B43: 45849 | C43: Francisco Javier Alvarez de la O | D43: 95 | E43: 3.5 | F43: =Table914[[#This Row],[Precio por Kg]]*Table914[[#This Row],[Peso del Organismo]] -> 332.5 | G43: 332.5 | H43: =Table914[[#This Row],[Precio del Organismo]]-Table914[[#This Row],[Pendiente]] -> 0
...

Sheet 1-2025
B2: EGRESOS | L2: INFORMACION RELEVANTE | O2: BIOMETRIAS
B3: Fecha | C3: Descripcion | D3: Piezas | E3: Precio Unitario | F3: Precio Total | G3: Proveedor | H3: Compro | I3: Tipo de Gasto | J3: Observacion | L3: No. de Ciclo | M3: 1-2025 | O3: Fecha | P3: Promedio de Peso [Gr.] | Q3: Dias Transcurridos
B4: 45707 | C4: 1.5 mm 4515 Aqua 45% Proteina | D4: 10.04 | E4: =_xlfn.XLOOKUP(Table576[[#This Row],[Descripcion]],Parametros!$B$3:$B$12,Parametros!$F$3:$F$12, "NO ENCONTRADO") -> 800 | F4: =D4*E4 -> 8032 | G4: =_xlfn.XLOOKUP(Table576[[#This Row],[Descripcion]],Parametros!$B$3:$B$12,Parametros!$D$3:$D$12, "NO ENCONTRADO") -> Rodolfo Sanchez | H4: GAC | I4: Produccion | L4: Fecha de Ingreso | M4: 27/01/2025 | O4: 45684 | P4: 0.6 | Q4: 0
B5: 45735 | C5: 2.5 mm 4515 Aqua 45% Proteina | D5: 2.588 | E5: =_xlfn.XLOOKUP(Table576[[#This Row],[Descripcion]],Parametros!$B$3:$B$12,Parametros!$F$3:$F$12, "NO ENCONTRADO") -> 587.5 | F5: =D5*E5 -> 1520.45 | G5: =_xlfn.XLOOKUP(Table576[[#This Row],[Descripcion]],Parametros!$B$3:$B$12,Parametros!$D$3:$D$12, "NO ENCONTRADO") -> Rodolfo Sanchez | H5: GAC | I5: Produccion | L5: No. de Organismos | M5: 18500 | O5: 45735 | P5: 27 | Q5: =_xlfn.DAYS(Table49[[#This Row],[Fecha]],O4) -> 51
B6: 45747 | C6: 2.5 mm 4515 Aqua 45% Proteina | D6: 8.24 | E6: =_xlfn.XLOOKUP(Table576[[#This Row],[Descripcion]],Parametros!$B$3:$B$12,Parametros!$F$3:$F$12, "NO ENCONTRADO") -> 587.5 | F6: =D6*E6 -> 4841 | G6: =_xlfn.XLOOKUP(Table576[[#This Row],[Descripcion]],Parametros!$B$3:$B$12,Parametros!$D$3:$D$12, "NO ENCONTRADO") -> Rodolfo Sanchez | H6: GAC | I6: Produccion | L6: Costo de compra por Organismo | M6: 0 | O6: 45754 | P6: 63 | Q6: =_xlfn.DAYS(Table49[[#This Row],[Fecha]],O5) -> 19
B7: 45754 | C7: 3.5 mm 3205 Aqua 32% Proteina | D7: 6.16 | E7: =_xlfn.XLOOKUP(Table576[[#This Row],[Descripcion]],Parametros!$B$3:$B$12,Parametros!$F$3:$F$12, "NO ENCONTRADO") -> 422.5 | F7: =D7*E7 -> 2602.6 | G7: =_xlfn.XLOOKUP(Table576[[#This Row],[Descripcion]],Parametros!$B$3:$B$12,Parametros!$D$3:$D$12, "NO ENCONTRADO") -> Rodolfo Sanchez | H7: GAC | I7: Produccion | L7: Costo de Produccion Total | M7: =Table576[[#Totals],[Precio Total]] -> 50965.05 | O7: 45778 | P7: 83 | Q7: =_xlfn.DAYS(Table49[[#This Row],[Fecha]],O6) -> 24
B8: 45758 | C8: 3.5 mm 3205 Aqua 32% Proteina | D8: 3.52 | E8: =_xlfn.XLOOKUP(Table576[[#This Row],[Descripcion]],Parametros!$B$3:$B$12,Parametros!$F$3:$F$12, "NO ENCONTRADO") -> 422.5 | F8: =D8*E8 -> 1487.2 | G8: =_xlfn.XLOOKUP(Table576[[#This Row],[Descripcion]],Parametros!$B$3:$B$12,Parametros!$D$3:$D$12, "NO ENCONTRADO") -> Rodolfo Sanchez | H8: GAC | I8: Produccion | L8: Costo de Produccion por Organismo | M8: =Table576[[#Totals],[Precio Total]]/M10 -> 33.9767 | O8: 45816 | P8: 99.4 | Q8: =_xlfn.DAYS(Table49[[#This Row],[Fecha]],O7) -> 38
B9: 31/04/2025 | C9: 3.5 mm 3205 Aqua 32% Proteina | D9: 8.68 | E9: =_xlfn.XLOOKUP(Table576[[#This Row],[Descripcion]],Parametros!$B$3:$B$12,Parametros!$F$3:$F$12, "NO ENCONTRADO") -> 422.5 | F9: =D9*E9 -> 3667.3 | G9: =_xlfn.XLOOKUP(Table576[[#This Row],[Descripcion]],Parametros!$B$3:$B$12,Parametros!$D$3:$D$12, "NO ENCONTRADO") -> Rodolfo Sanchez | H9: GAC | I9: Produccion | L9: Mortandad | M9: 17000 | O9: 45857 | P9: 182.4 | Q9: =_xlfn.DAYS(Table49[[#This Row],[Fecha]],O8) -> 41
B10: 45808 | C10: 3.5 mm 3205 Aqua 32% Proteina | D10: 6.24 | E10: =_xlfn.XLOOKUP(Table576[[#This Row],[Descripcion]],Parametros!$B$3:$B$12,Parametros!$F$3:$F$12, "NO ENCONTRADO") -> 422.5 | F10: =D10*E10 -> 2636.4 | G10: =_xlfn.XLOOKUP(Table576[[#This Row],[Descripcion]],Parametros!$B$3:$B$12,Parametros!$D$3:$D$12, "NO ENCONTRADO") -> Rodolfo Sanchez | H10: GAC | I10: Produccion | L10: Organismos Aprovechados | M10: =M5-M9 -> 1500 | O10: 45874 | P10: 237 | Q10: =_xlfn.DAYS(Table49[[#This Row],[Fecha]],O9) -> 17
B11: 31/06/2025 | C11: 3.5 mm 3205 Aqua 32% Proteina | D11: 8.4 | E11: =_xlfn.XLOOKUP(Table576[[#This Row],[Descripcion]],Parametros!$B$3:$B$12,Parametros!$F$3:$F$12, "NO ENCONTRADO") -> 422.5 | F11: =D11*E11 -> 3549 | G11: =_xlfn.XLOOKUP(Table576[[#This Row],[Descripcion]],Parametros!$B$3:$B$12,Parametros!$D$3:$D$12, "NO ENCONTRADO") -> Rodolfo Sanchez | H11: GAC | I11: Produccion | L11: Participacion por Organismo | M11: =100/M5 -> 0.0054054054 | O11: 45882 | P11: 282 | Q11: =_xlfn.DAYS(Table49[[#This Row],[Fecha]],O10) -> 8
B12: 45862 | C12: 3.5 mm 3205 Aqua 32% Proteina | D12: 7.56 | E12: =_xlfn.XLOOKUP(Table576[[#This Row],[Descripcion]],Parametros!$B$3:$B$12,Parametros!$F$3:$F$12, "NO ENCONTRADO") -> 422.5 | F12: =D12*E12 -> 3194.1 | G12: =_xlfn.XLOOKUP(Table576[[#This Row],[Descripcion]],Parametros!$B$3:$B$12,Parametros!$D$3:$D$12, "NO ENCONTRADO") -> Rodolfo Sanchez | H12: GAC | I12: Produccion | L12: Ventas Realizadas | M12: =Table9148[[#Totals],[Fecha]] -> 9 | O12: 45895 | P12: 330 | Q12: =_xlfn.DAYS(Table49[[#This Row],[Fecha]],O11) -> 13
B13: 45877 | C13: 3.5 mm 3205 Aqua 32% Proteina | D13: 5 | E13: =_xlfn.XLOOKUP(Table576[[#This Row],[Descripcion]],Parametros!$B$3:$B$12,Parametros!$F$3:$F$12, "NO ENCONTRADO") -> 422.5 | F13: =D13*E13 -> 2112.5 | G13: =_xlfn.XLOOKUP(Table576[[#This Row],[Descripcion]],Parametros!$B$3:$B$12,Parametros!$D$3:$D$12, "NO ENCONTRADO") -> Rodolfo Sanchez | H13: GAC | I13: Produccion | L13: Organismos Restantes | M13: =M10-((M15/P16)*1000) -> 412.66667 | O13: 45919 | P13: 400 | Q13: =_xlfn.DAYS(Table49[[#This Row],[Fecha]],O12) -> 24
B14: 45907 | C14: 5.0 mm 3005 Aqua 30% Proteina | D14: 15 | E14: =_xlfn.XLOOKUP(Table576[[#This Row],[Descripcion]],Parametros!$B$3:$B$12,Parametros!$F$3:$F$12, "NO ENCONTRADO") -> 422.5 | F14: =D14*E14 -> 6337.5 | G14: =_xlfn.XLOOKUP(Table576[[#This Row],[Descripcion]],Parametros!$B$3:$B$12,Parametros!$D$3:$D$12, "NO ENCONTRADO") -> Rodolfo Sanchez | H14: GAC | I14: Produccion | L14: Biomasa Estimada | M14: =(M13*P16)/1000 -> 241.41 | O14: 45934 | P14: 436 | Q14: =_xlfn.DAYS(Table49[[#This Row],[Fecha]],O13) -> 15
B15: 45926 | C15: 5.0 mm 3005 Aqua 30% Proteina | D15: 10 | E15: =_xlfn.XLOOKUP(Table576[[#This Row],[Descripcion]],Parametros!$B$3:$B$12,Parametros!$F$3:$F$12, "NO ENCONTRADO") -> 422.5 | F15: =D15*E15 -> 4225 | G15: =_xlfn.XLOOKUP(Table576[[#This Row],[Descripcion]],Parametros!$B$3:$B$12,Parametros!$D$3:$D$12, "NO ENCONTRADO") -> Rodolfo Sanchez | H15: GAC | I15: Produccion | L15: Biomasa Vendida | M15: =Table9148[[#Totals],[Peso del Organismo]] -> 636.09 | O15: 45946 | P15: 470 | Q15: =_xlfn.DAYS(Table49[[#This Row],[Fecha]],O14) -> 12
B16: 45964 | C16: 3.5 mm 3205 Aqua 32% Proteina | D16: 10 | E16: =_xlfn.XLOOKUP(Table576[[#This Row],[Descripcion]],Parametros!$B$3:$B$12,Parametros!$F$3:$F$12, "NO ENCONTRADO") -> 422.5 | F16: =D16*E16 -> 4225 | G16: =_xlfn.XLOOKUP(Table576[[#This Row],[Descripcion]],Parametros!$B$3:$B$12,Parametros!$D$3:$D$12, "NO ENCONTRADO") -> Rodolfo Sanchez | H16: GAC | I16: Produccion | L16: Promedio de Peso | M16: =M15/M12 -> 70.676667 | O16: 45993 | P16: 585 | Q16: =_xlfn.DAYS(Table49[[#This Row],[Fecha]],O15) -> 47
B17: 45993 | C17: 5.0 mm 3005 Aqua 30% Proteina | D17: 6 | E17: =_xlfn.XLOOKUP(Table576[[#This Row],[Descripcion]],Parametros!$B$3:$B$12,Parametros!$F$3:$F$12, "NO ENCONTRADO") -> 422.5 | F17: =D17*E17 -> 2535 | G17: =_xlfn.XLOOKUP(Table576[[#This Row],[Descripcion]],Parametros!$B$3:$B$12,Parametros!$D$3:$D$12, "NO ENCONTRADO") -> Rodolfo Sanchez | H17: GAC | I17: Produccion | L17: Fecha Actualizada | M17: 08/01/2026
F18: =SUM(F4:F17) -> 50965.05 | L18: Dias Transcurridos del Ciclo | M18: =M17-M4 -> 346
B19: INFORMACION DE PARTICIPANTES
B20: Animales Iniciales | C20: Participantes | D20: Participacion [%] | E20: Animales Restantes | F20: Gasto | G20: Ingreso | H20: Pago | I20: Restante
B21: =M5 -> 18500 | C21: Granja Acuicola La Ceiba | D21: =(B21*$M$11)/100 -> 1 | E21: =$M$10*D21 -> 1500 | F21: =Table576[[#Totals],[Precio Total]] -> 50965.05 | G21: =(Table9148[[#Totals],[Pago]]/$M$10)*E21 -> 45110.3 | H21: =G21 -> 45110.3 | I21: =F21-H21 -> 5854.75
E22: =SUBTOTAL(109,Table87[Animales Restantes]) -> 1500 | F22: =SUBTOTAL(109,Table87[Gasto]) -> 50965.05 | G22: =SUBTOTAL(109,Table87[Ingreso]) -> 45110.3 | H22: =SUBTOTAL(109,Table87[Pago]) -> 45110.3 | I22: =SUBTOTAL(109,Table87[Restante]) -> 5854.75
B24: VENTAS
B25: Fecha | C25: Cliente | D25: Precio por Kg | E25: Peso del Organismo | F25: Precio del Organismo | G25: Pendiente | H25: Pago | I25: Observaciones | J25: Metodo de Pago
B26: 45881 | C26: Mecanico Marcha Planta | D26: 125 | E26: 6.2 | F26: =Table9148[[#This Row],[Precio por Kg]]*Table9148[[#This Row],[Peso del Organismo]] -> 775 | G26: 0 | H26: =Table9148[[#This Row],[Precio del Organismo]]-Table9148[[#This Row],[Pendiente]] -> 775 | J26: Trueque
B27: 45934 | C27: Yara Odilia Rivera Marquez | D27: 70 | E27: 4.795 | F27: =Table9148[[#This Row],[Precio por Kg]]*Table9148[[#This Row],[Peso del Organismo]] -> 335.65 | G27: 0 | H27: =Table9148[[#This Row],[Precio del Organismo]]-Table9148[[#This Row],[Pendiente]] -> 335.65 | J27: Transferencia
B28: 45934 | C28: Jose Daniel Alvarez de la O | D28: 70 | E28: 13.795 | F28: =Table9148[[#This Row],[Precio por Kg]]*Table9148[[#This Row],[Peso del Organismo]] -> 965.65 | G28: 0 | H28: =Table9148[[#This Row],[Precio del Organismo]]-Table9148[[#This Row],[Pendiente]] -> 965.65 | J28: Descuento Nomina
B29: 45974 | C29: Chavos Granja | D29: 0 | E29: 4 | F29: =Table9148[[#This Row],[Precio por Kg]]*Table9148[[#This Row],[Peso del Organismo]] -> 0 | G29: 0 | H29: 0 | J29: Mortalidad por cocodrilo
B30: 45664 | C30: Ernesto Chable | D30: 70 | E30: 282.15 | F30: =Table9148[[#This Row],[Precio por Kg]]*Table9148[[#This Row],[Peso del Organismo]] -> 19750.5 | H30: =Table9148[[#This Row],[Precio del Organismo]]-Table9148[[#This Row],[Pendiente]] -> 19750.5 | J30: Transferencia
B31: 45664 | C31: Contador Roberto | D31: 91.743119 | E31: 10.9 | F31: =Table9148[[#This Row],[Precio por Kg]]*Table9148[[#This Row],[Peso del Organismo]] -> 1000 | H31: =Table9148[[#This Row],[Precio del Organismo]]-Table9148[[#This Row],[Pendiente]] -> 1000 | J31: Efectivo
B32: 45664 | C32: Publico General | D32: 90 | E32: 5 | F32: =Table9148[[#This Row],[Precio por Kg]]*Table9148[[#This Row],[Peso del Organismo]] -> 450 | H32: =Table9148[[#This Row],[Precio del Organismo]]-Table9148[[#This Row],[Pendiente]] -> 450 | J32: Efectivo
B33: 45664 | C33: Publico General | D33: 90.217391 | E33: 9.2 | F33: =Table9148[[#This Row],[Precio por Kg]]*Table9148[[#This Row],[Peso del Organismo]] -> 830 | H33: =Table9148[[#This Row],[Precio del Organismo]]-Table9148[[#This Row],[Pendiente]] -> 830 | J33: Efectivo
B34: 45666 | C34: Ernesto Chable | D34: 70 | E34: 300.05 | F34: =Table9148[[#This Row],[Precio por Kg]]*Table9148[[#This Row],[Peso del Organismo]] -> 21003.5 | H34: =Table9148[[#This Row],[Precio del Organismo]]-Table9148[[#This Row],[Pendiente]] -> 21003.5
B35: =SUBTOTAL(103,Table9148[Fecha]) -> 9 | D35: =SUBTOTAL(101,Table9148[Precio por Kg]) -> 75.217835 | E35: =SUBTOTAL(109,Table9148[Peso del Organismo]) -> 636.09 | F35: =SUBTOTAL(109,Table9148[Precio del Organismo]) -> 45110.3 | G35: =SUBTOTAL(109,Table9148[Pendiente]) -> 0 | H35: =SUBTOTAL(109,Table9148[Pago]) -> 45110.3

Sheet 2-2025
B2: EGRESOS | L2: INFORMACION RELEVANTE | O2: BIOMETRIAS
B3: Fecha | C3: Descripcion | D3: Piezas | E3: Precio Unitario | F3: Precio Total | G3: Proveedor | H3: Compro | I3: Tipo de Gasto | J3: Observacion | L3: No. de Ciclo | M3: 2-2025 | O3: Fecha | P3: Promedio de Peso [Gr.] | Q3: Dias Transcurridos
B4: 45877 | C4: 1.5 mm 4515 Aqua 45% Proteina | D4: 3 | E4: =_xlfn.XLOOKUP(Table57610[[#This Row],[Descripcion]],Parametros!$B$3:$B$12,Parametros!$F$3:$F$12, "NO ENCONTRADO") -> 800 | F4: =D4*E4 -> 2400 | G4: =_xlfn.XLOOKUP(Table57610[[#This Row],[Descripcion]],Parametros!$B$3:$B$12,Parametros!$D$3:$D$12, "NO ENCONTRADO") -> Rodolfo Sanchez | H4: GAC | I4: Produccion | L4: Fecha de Ingreso | M4: 05/07/2025 | O4: 45843 | P4: 0.7 | Q4: 0
B5: 45877 | C5: 2.5 mm 4515 Aqua 45% Proteina | D5: 4 | E5: =_xlfn.XLOOKUP(Table57610[[#This Row],[Descripcion]],Parametros!$B$3:$B$12,Parametros!$F$3:$F$12, "NO ENCONTRADO") -> 587.5 | F5: =D5*E5 -> 2350 | G5: =_xlfn.XLOOKUP(Table57610[[#This Row],[Descripcion]],Parametros!$B$3:$B$12,Parametros!$D$3:$D$12, "NO ENCONTRADO") -> Rodolfo Sanchez | H5: GAC | I5: Produccion | L5: No. de Organismos | M5: 18950 | O5: 45874 | P5: 7 | Q5: =_xlfn.DAYS(O5,O4) -> 31
B6: 45907 | C6: 2.5 mm 4515 Aqua 45% Proteina | D6: 6 | E6: =_xlfn.XLOOKUP(Table57610[[#This Row],[Descripcion]],Parametros!$B$3:$B$12,Parametros!$F$3:$F$12, "NO ENCONTRADO") -> 587.5 | F6: =D6*E6 -> 3525 | G6: =_xlfn.XLOOKUP(Table57610[[#This Row],[Descripcion]],Parametros!$B$3:$B$12,Parametros!$D$3:$D$12, "NO ENCONTRADO") -> Rodolfo Sanchez | H6: GAC | I6: Produccion | L6: Costo de compra por Organismo | M6: 0 | O6: 45895 | P6: 27 | Q6: =_xlfn.DAYS(O6,O5) -> 21
B7: 45926 | C7: 2.5 mm 4515 Aqua 45% Proteina | D7: 8 | E7: =_xlfn.XLOOKUP(Table57610[[#This Row],[Descripcion]],Parametros!$B$3:$B$12,Parametros!$F$3:$F$12, "NO ENCONTRADO") -> 587.5 | F7: =D7*E7 -> 4700 | G7: =_xlfn.XLOOKUP(Table57610[[#This Row],[Descripcion]],Parametros!$B$3:$B$12,Parametros!$D$3:$D$12, "NO ENCONTRADO") -> Rodolfo Sanchez | H7: GAC | I7: Produccion | L7: Costo de Produccion Total | M7: =Table57610[[#Totals],[Precio Total]] -> 17622.5 | O7: 45919 | P7: 53.3 | Q7: =_xlfn.DAYS(O7,O6) -> 24
B8: 45964 | C8: 3.5 mm 3205 Aqua 32% Proteina | D8: 6 | E8: =_xlfn.XLOOKUP(Table57610[[#This Row],[Descripcion]],Parametros!$B$3:$B$12,Parametros!$F$3:$F$12, "NO ENCONTRADO") -> 422.5 | F8: =D8*E8 -> 2535 | G8: =_xlfn.XLOOKUP(Table57610[[#This Row],[Descripcion]],Parametros!$B$3:$B$12,Parametros!$D$3:$D$12, "NO ENCONTRADO") -> Rodolfo Sanchez | H8: GAC | I8: Produccion | L8: Costo de Produccion por Organismo | M8: =Table57610[[#Totals],[Precio Total]]/M10 -> 0.92994723 | O8: 45946 | P8: 140 | Q8: =_xlfn.DAYS(O8,O7) -> 27
B9: 45993 | C9: 3.5 mm 3205 Aqua 32% Proteina | D9: 5 | E9: =_xlfn.XLOOKUP(Table57610[[#This Row],[Descripcion]],Parametros!$B$3:$B$12,Parametros!$F$3:$F$12, "NO ENCONTRADO") -> 422.5 | F9: =D9*E9 -> 2112.5 | G9: =_xlfn.XLOOKUP(Table57610[[#This Row],[Descripcion]],Parametros!$B$3:$B$12,Parametros!$D$3:$D$12, "NO ENCONTRADO") -> Rodolfo Sanchez | H9: GAC | I9: Produccion | L9: Mortandad | M9: 0 | O9: 45993 | P9: 273 | Q9: =_xlfn.DAYS(O9,O8) -> 47
F10: =SUM(F4:F9) -> 17622.5 | L10: Organismos Aprovechados | M10: =M5-M9 -> 18950
B11: INFORMACION DE PARTICIPANTES | L11: Participacion por Organismo | M11: =100/M5 -> 0.0052770449
B12: Animales Iniciales | C12: Participantes | D12: Participacion [%] | E12: Animales Restantes | F12: Gasto | G12: Ingreso | H12: Pago | I12: Restante | L12: Ventas Realizadas | M12: =Table914812[[#Totals],[Fecha]] -> 2
B13: =M5 -> 18950 | C13: Granja Acuicola La Ceiba | D13: =(B13*$M$11)/100 -> 1 | E13: =$M$10*D13 -> 18950 | F13: =Table57610[[#Totals],[Precio Total]] -> 17622.5 | G13: =(Table914812[[#Totals],[Pago]]/$M$10)*E13 -> 18322.5 | H13: =G13 -> 18322.5 | I13: =F13-H13 -> -700 | L13: Organismos Restantes | M13: =M10-M12 -> 18948
E14: =SUBTOTAL(109,Table8711[Animales Restantes]) -> 18950 | F14: =SUBTOTAL(109,Table8711[Gasto]) -> 17622.5 | G14: =SUBTOTAL(109,Table8711[Ingreso]) -> 18322.5 | H14: =SUBTOTAL(109,Table8711[Pago]) -> 18322.5 | I14: =SUBTOTAL(109,Table8711[Restante]) -> -700 | L14: Biomasa Estimada | M14: =(M13*P9)/1000 -> 5172.804
L15: Biomasa Vendida | M15: =Table914812[[#Totals],[Peso del Organismo]] -> 261.75
B16: VENTAS | L16: Promedio de Peso | M16: =M15/M12 -> 130.875
B17: Fecha | C17: Cliente | D17: Precio por Kg | E17: Peso del Organismo | F17: Precio del Organismo | G17: Pendiente | H17: Pago | I17: Observaciones | J17: Metodo de Pago | L17: Fecha Actualizada | M17: 22/09/2025
B18: 45664 | C18: Ernesto Chable | D18: 70 | E18: 236.25 | F18: =Table914812[[#This Row],[Precio por Kg]]*Table914812[[#This Row],[Peso del Organismo]] -> 16537.5 | G18: 0 | H18: =Table914812[[#This Row],[Precio del Organismo]]-Table914812[[#This Row],[Pendiente]] -> 16537.5 | L18: Dias Transcurridos del Ciclo | M18: =M17-M4 -> 79
B19: 45666 | C19: Ernesto Chable | D19: 70 | E19: 25.5 | F19: =Table914812[[#This Row],[Precio por Kg]]*Table914812[[#This Row],[Peso del Organismo]] -> 1785 | G19: 0 | H19: =Table914812[[#This Row],[Precio del Organismo]]-Table914812[[#This Row],[Pendiente]] -> 1785
D20: 0 | F20: =Table914812[[#This Row],[Precio por Kg]]*Table914812[[#This Row],[Peso del Organismo]] -> 0 | G20: 0 | H20: =Table914812[[#This Row],[Precio del Organismo]]-Table914812[[#This Row],[Pendiente]] -> 0
D21: 0 | F21: =Table914812[[#This Row],[Precio por Kg]]*Table914812[[#This Row],[Peso del Organismo]] -> 0 | G21: 0 | H21: =Table914812[[#This Row],[Precio del Organismo]]-Table914812[[#This Row],[Pendiente]] -> 0
B22: =SUBTOTAL(103,Table914812[Fecha]) -> 2 | D22: =SUBTOTAL(101,Table914812[Precio por Kg]) -> 35 | E22: =SUBTOTAL(109,Table914812[Peso del Organismo]) -> 261.75 | F22: =SUBTOTAL(109,Table914812[Precio del Organismo]) -> 18322.5 | G22: =SUBTOTAL(109,Table914812[Pendiente]) -> 0 | H22: =SUBTOTAL(109,Table914812[Pago]) -> 18322.5

Sheet 3-2025
B2: EGRESOS | L2: INFORMACION RELEVANTE | O2: BIOMETRIAS
B3: Fecha | C3: Descripcion | D3: Piezas | E3: Precio Unitario | F3: Precio Total | G3: Proveedor | H3: Compro | I3: Tipo de Gasto | J3: Observacion | L3: No. de Ciclo | M3: 3-2025 | O3: Fecha | P3: Promedio de Peso [Gr.] | Q3: Dias Transcurridos
B4: 45907 | C4: 1.5 mm 4515 Aqua 45% Proteina | D4: 4 | E4: =_xlfn.XLOOKUP(Table5761014[[#This Row],[Descripcion]],Parametros!$B$3:$B$12,Parametros!$F$3:$F$12, "NO ENCONTRADO") -> 800 | F4: =D4*E4 -> 3200 | G4: =_xlfn.XLOOKUP(Table57610[[#This Row],[Descripcion]],Parametros!$B$3:$B$12,Parametros!$D$3:$D$12, "NO ENCONTRADO") -> Rodolfo Sanchez | H4: GAC | I4: Produccion | L4: Fecha de Ingreso | M4: 08/08/2025 | O4: 45877 | P4: 2 | Q4: 0
B5: 45907 | C5: 2.5 mm 4515 Aqua 45% Proteina | D5: 4 | E5: =_xlfn.XLOOKUP(Table5761014[[#This Row],[Descripcion]],Parametros!$B$3:$B$12,Parametros!$F$3:$F$12, "NO ENCONTRADO") -> 587.5 | F5: =D5*E5 -> 2350 | G5: =_xlfn.XLOOKUP(Table57610[[#This Row],[Descripcion]],Parametros!$B$3:$B$12,Parametros!$D$3:$D$12, "NO ENCONTRADO") -> Rodolfo Sanchez | H5: GAC | I5: Produccion | L5: No. de Organismos | M5: 17000 | O5: 45895 | P5: 12.15 | Q5: =_xlfn.DAYS(O5,O4) -> 18
B6: 45926 | C6: 2.5 mm 4515 Aqua 45% Proteina | D6: 8 | E6: =_xlfn.XLOOKUP(Table5761014[[#This Row],[Descripcion]],Parametros!$B$3:$B$12,Parametros!$F$3:$F$12, "NO ENCONTRADO") -> 587.5 | F6: =D6*E6 -> 4700 | G6: =_xlfn.XLOOKUP(Table57610[[#This Row],[Descripcion]],Parametros!$B$3:$B$12,Parametros!$D$3:$D$12, "NO ENCONTRADO") -> Rodolfo Sanchez | H6: GAC | I6: Produccion | L6: Costo de compra por Organismo | M6: 0 | O6: 45919 | P6: 27.7 | Q6: =_xlfn.DAYS(O6,O5) -> 24
B7: 45964 | C7: 3.5 mm 3205 Aqua 32% Proteina | D7: 6 | E7: =_xlfn.XLOOKUP(Table5761014[[#This Row],[Descripcion]],Parametros!$B$3:$B$12,Parametros!$F$3:$F$12, "NO ENCONTRADO") -> 422.5 | F7: =D7*E7 -> 2535 | G7: =_xlfn.XLOOKUP(Table57610[[#This Row],[Descripcion]],Parametros!$B$3:$B$12,Parametros!$D$3:$D$12, "NO ENCONTRADO") -> Rodolfo Sanchez | H7: GAC | I7: Produccion | L7: Costo de Produccion Total | M7: =Table5761014[[#Totals],[Precio Total]] -> 20812.5 | O7: 45946 | P7: 105 | Q7: =_xlfn.DAYS(O7,O6) -> 27
B8: 45993 | C8: 3.5 mm 3205 Aqua 32% Proteina | D8: 9 | E8: =_xlfn.XLOOKUP(Table5761014[[#This Row],[Descripcion]],Parametros!$B$3:$B$12,Parametros!$F$3:$F$12, "NO ENCONTRADO") -> 422.5 | F8: =D8*E8 -> 3802.5 | G8: =_xlfn.XLOOKUP(Table57610[[#This Row],[Descripcion]],Parametros!$B$3:$B$12,Parametros!$D$3:$D$12, "NO ENCONTRADO") -> Rodolfo Sanchez | H8: GAC | I8: Produccion | L8: Costo de Produccion por Organismo | M8: =Table5761014[[#Totals],[Precio Total]]/M10 -> 1.2242647 | O8: 45993 | P8: 177 | Q8: =_xlfn.DAYS(O8,O7) -> 47
B9: 45993 | C9: 5.0 mm 3005 Aqua 30% Proteina | D9: 10 | E9: =_xlfn.XLOOKUP(Table5761014[[#This Row],[Descripcion]],Parametros!$B$3:$B$12,Parametros!$F$3:$F$12, "NO ENCONTRADO") -> 422.5 | F9: =D9*E9 -> 4225 | G9: =_xlfn.XLOOKUP(Table57610[[#This Row],[Descripcion]],Parametros!$B$3:$B$12,Parametros!$D$3:$D$12, "NO ENCONTRADO") -> Rodolfo Sanchez | L9: Mortandad | M9: 0 | O9: 46059 | P9: 314 | Q9: =_xlfn.DAYS(O9,O8) -> 66
F10: =SUM(F4:F9) -> 20812.5 | L10: Organismos Aprovechados | M10: =M5-M9 -> 17000 | O10: 46105 | P10: 403 | Q10: =_xlfn.DAYS(O10,O9) -> 46
B11: INFORMACION DE PARTICIPANTES | L11: Participacion por Organismo | M11: =100/M5 -> 0.0058823529
B12: Animales Iniciales | C12: Participantes | D12: Participacion [%] | E12: Animales Restantes | F12: Gasto | G12: Ingreso | H12: Pago | I12: Restante | L12: Ventas Realizadas | M12: =Table91481216[[#Totals],[Fecha]] -> 0
B13: =M5 -> 17000 | C13: Granja Acuicola La Ceiba | D13: =(B13*$M$11)/100 -> 1 | E13: =$M$10*D13 -> 17000 | F13: 9198.7444 | G13: =(Table91481216[[#Totals],[Pago]]/$M$10)*E13 -> 0 | H13: =G13 -> 0 | I13: =F13-H13 -> 9198.7444 | L13: Organismos Restantes | M13: =M10-M12 -> 17000
E14: =SUBTOTAL(109,Table871115[Animales Restantes]) -> 17000 | F14: =SUBTOTAL(109,Table871115[Gasto]) -> 9198.7444 | G14: =SUBTOTAL(109,Table871115[Ingreso]) -> 0 | H14: =SUBTOTAL(109,Table871115[Pago]) -> 0 | I14: =SUBTOTAL(109,Table871115[Restante]) -> 9198.7444 | L14: Biomasa Estimada | M14: =(M13*P8)/1000 -> 3009
L15: Biomasa Vendida | M15: =Table91481216[[#Totals],[Peso del Organismo]] -> 0
B16: VENTAS | L16: Promedio de Peso | M16: =M15/M12 -> #DIV/0!
B17: Fecha | C17: Cliente | D17: Precio por Kg | E17: Peso del Organismo | F17: Precio del Organismo | G17: Pendiente | H17: Pago | I17: Observaciones | J17: Metodo de Pago | L17: Fecha Actualizada | M17: 13/09/2025
D18: 0 | F18: =Table91481216[[#This Row],[Precio por Kg]]*Table91481216[[#This Row],[Peso del Organismo]] -> 0 | G18: 0 | H18: =Table91481216[[#This Row],[Precio del Organismo]]-Table91481216[[#This Row],[Pendiente]] -> 0 | L18: Dias Transcurridos del Ciclo | M18: =M17-M4 -> 36
D19: 0 | F19: =Table91481216[[#This Row],[Precio por Kg]]*Table91481216[[#This Row],[Peso del Organismo]] -> 0 | G19: 0 | H19: =Table91481216[[#This Row],[Precio del Organismo]]-Table91481216[[#This Row],[Pendiente]] -> 0
D20: 0 | F20: =Table91481216[[#This Row],[Precio por Kg]]*Table91481216[[#This Row],[Peso del Organismo]] -> 0 | G20: 0 | H20: =Table91481216[[#This Row],[Precio del Organismo]]-Table91481216[[#This Row],[Pendiente]] -> 0
D21: 0 | F21: =Table91481216[[#This Row],[Precio por Kg]]*Table91481216[[#This Row],[Peso del Organismo]] -> 0 | G21: 0 | H21: =Table91481216[[#This Row],[Precio del Organismo]]-Table91481216[[#This Row],[Pendiente]] -> 0
B22: =SUBTOTAL(103,Table91481216[Fecha]) -> 0 | D22: =SUBTOTAL(101,Table91481216[Precio por Kg]) -> 0 | E22: =SUBTOTAL(109,Table91481216[Peso del Organismo]) -> 0 | F22: =SUBTOTAL(109,Table91481216[Precio del Organismo]) -> 0 | G22: =SUBTOTAL(109,Table91481216[Pendiente]) -> 0 | H22: =SUBTOTAL(109,Table91481216[Pago]) -> 0

Sheet Parametros
B2: Descripcion | C2: Marca | D2: Proveedor | E2: Presentacion | F2: Precio Bulto | G2: Precio Kg
B3: 0.3 mm 5215 Aqua 52% Proteina | C3: VIMIFOS | D3: Rodolfo Sanchez | E3: 10 | F3: 495 | G3: =F3/E3 -> 49.5
B4: 0.4 mm Microteck (MCK) Hormonado | C4: PEDREGAL | D4: JYY Agropecuaria | E4: 25 | F4: 2196 | G4: =F4/E4 -> 87.84
B5: 0.4 mm Microteck (MCK) Sin Hormonar | C5: VIMIFOS | D5: Rodolfo Sanchez | E5: 25 | F5: 986 | G5: =F5/E5 -> 39.44
B6: 1.5 mm 4515 Aqua 45% Proteina | C6: VIMIFOS | D6: Rodolfo Sanchez | E6: 25 | F6: 800 | G6: =F6/E6 -> 32
B7: 2.5 mm 4515 Aqua 45% Proteina | C7: VIMIFOS | D7: Rodolfo Sanchez | E7: 25 | F7: 587.5 | G7: =F7/E7 -> 23.5
B8: 3.5 mm 3205 Aqua 32% Proteina | C8: VIMIFOS | D8: Rodolfo Sanchez | E8: 25 | F8: 422.5 | G8: =F8/E8 -> 16.9
B9: 5.0 mm 3005 Aqua 30% Proteina | C9: VIMIFOS | D9: Rodolfo Sanchez | E9: 25 | F9: 422.5 | G9: =F9/E9 -> 16.9
B10: Dyno Alimento para perro | C10: DYNO | D10: JYY Agropecuaria | E10: 25 | F10: =353.45*1.16 -> 410.002 | G10: =F10/E10 -> 16.40008
B11: Melaza | C11: GENERICO | D11: JYY Agropecuaria | E11: 25 | F11: 180 | G11: =F11/E11 -> 7.2 | H11: No genera IVA
B12: Sal Refinada Sin Yodo | C12: GENERICO | D12: JYY Agropecuaria | E12: 50 | F12: =213 -> 213 | G12: =F12/E12 -> 4.26 | H12: No genera IVA

Sheet Sheet1
B2: Siembra 1-2025 (Estanque 6) | L2: Siembra 2-2025 (Estanque CH-01) | V2: Siembra 3-2025
B3: EGRESOS | L3: EGRESOS | V3: EGRESOS
B4: Fecha | C4: Descripcion | D4: Piezas | E4: Precio Unitario | F4: Precio Total | G4: Proveedor | H4: Compro | I4: Tipo de Gasto | J4: Observacion | L4: Fecha | M4: Descripcion | N4: Piezas | O4: Precio Unitario | P4: Precio Total | Q4: Proveedor | R4: Compro | S4: Tipo de Gasto | T4: Observacion | V4: Fecha | W4: Descripcion | X4: Piezas | Y4: Precio Unitario | Z4: Precio Total | AA4: Proveedor | AB4: Compro | AC4: Tipo de Gasto | AD4: Observacion
B5: 45707 | C5: 1.5 mm 4515 Aqua 45% Proteina | D5: 10.04 | E5: =_xlfn.XLOOKUP(Table57618[[#This Row],[Descripcion]],Parametros!$B$3:$B$12,Parametros!$F$3:$F$12, "NO ENCONTRADO") -> 800 | F5: =D5*E5 -> 8032 | G5: =_xlfn.XLOOKUP(Table57618[[#This Row],[Descripcion]],Parametros!$B$3:$B$12,Parametros!$D$3:$D$12, "NO ENCONTRADO") -> Rodolfo Sanchez | H5: GAC | I5: Produccion | L5: 45877 | M5: 1.5 mm 4515 Aqua 45% Proteina | N5: 3 | O5: =_xlfn.XLOOKUP(Table5761020[[#This Row],[Descripcion]],Parametros!$B$3:$B$12,Parametros!$F$3:$F$12, "NO ENCONTRADO") -> 800 | P5: =N5*O5 -> 2400 | Q5: =_xlfn.XLOOKUP(Table5761020[[#This Row],[Descripcion]],Parametros!$B$3:$B$12,Parametros!$D$3:$D$12, "NO ENCONTRADO") -> Rodolfo Sanchez | R5: GAC | S5: Produccion | V5: 45907 | W5: 1.5 mm 4515 Aqua 45% Proteina | X5: 4 | Y5: 800 | Z5: =X5*Y5 -> 3200 | AA5: =_xlfn.XLOOKUP(Table57610[[#This Row],[Descripcion]],Parametros!$B$3:$B$12,Parametros!$D$3:$D$12, "NO ENCONTRADO") -> Rodolfo Sanchez | AB5: GAC | AC5: Produccion
B6: 45735 | C6: 2.5 mm 4515 Aqua 45% Proteina | D6: 2.588 | E6: =_xlfn.XLOOKUP(Table57618[[#This Row],[Descripcion]],Parametros!$B$3:$B$12,Parametros!$F$3:$F$12, "NO ENCONTRADO") -> 587.5 | F6: =D6*E6 -> 1520.45 | G6: =_xlfn.XLOOKUP(Table57618[[#This Row],[Descripcion]],Parametros!$B$3:$B$12,Parametros!$D$3:$D$12, "NO ENCONTRADO") -> Rodolfo Sanchez | H6: GAC | I6: Produccion | L6: 45877 | M6: 2.5 mm 4515 Aqua 45% Proteina | N6: 4 | O6: =_xlfn.XLOOKUP(Table5761020[[#This Row],[Descripcion]],Parametros!$B$3:$B$12,Parametros!$F$3:$F$12, "NO ENCONTRADO") -> 587.5 | P6: =N6*O6 -> 2350 | Q6: =_xlfn.XLOOKUP(Table5761020[[#This Row],[Descripcion]],Parametros!$B$3:$B$12,Parametros!$D$3:$D$12, "NO ENCONTRADO") -> Rodolfo Sanchez | R6: GAC | S6: Produccion | V6: 45907 | W6: 2.5 mm 4515 Aqua 45% Proteina | X6: 4 | Y6: 587.5 | Z6: =X6*Y6 -> 2350 | AA6: =_xlfn.XLOOKUP(Table57610[[#This Row],[Descripcion]],Parametros!$B$3:$B$12,Parametros!$D$3:$D$12, "NO ENCONTRADO") -> Rodolfo Sanchez | AB6: GAC | AC6: Produccion
B7: 45747 | C7: 2.5 mm 4515 Aqua 45% Proteina | D7: 8.24 | E7: =_xlfn.XLOOKUP(Table57618[[#This Row],[Descripcion]],Parametros!$B$3:$B$12,Parametros!$F$3:$F$12, "NO ENCONTRADO") -> 587.5 | F7: =D7*E7 -> 4841 | G7: =_xlfn.XLOOKUP(Table57618[[#This Row],[Descripcion]],Parametros!$B$3:$B$12,Parametros!$D$3:$D$12, "NO ENCONTRADO") -> Rodolfo Sanchez | H7: GAC | I7: Produccion | L7: 45907 | M7: 2.5 mm 4515 Aqua 45% Proteina | N7: 6 | O7: =_xlfn.XLOOKUP(Table5761020[[#This Row],[Descripcion]],Parametros!$B$3:$B$12,Parametros!$F$3:$F$12, "NO ENCONTRADO") -> 587.5 | P7: =N7*O7 -> 3525 | Q7: =_xlfn.XLOOKUP(Table5761020[[#This Row],[Descripcion]],Parametros!$B$3:$B$12,Parametros!$D$3:$D$12, "NO ENCONTRADO") -> Rodolfo Sanchez | R7: GAC | S7: Produccion | Z7: =SUM(Z5:Z6) -> 5550
B8: 45754 | C8: 3.5 mm 3205 Aqua 32% Proteina | D8: 6.16 | E8: =_xlfn.XLOOKUP(Table57618[[#This Row],[Descripcion]],Parametros!$B$3:$B$12,Parametros!$F$3:$F$12, "NO ENCONTRADO") -> 422.5 | F8: =D8*E8 -> 2602.6 | G8: =_xlfn.XLOOKUP(Table57618[[#This Row],[Descripcion]],Parametros!$B$3:$B$12,Parametros!$D$3:$D$12, "NO ENCONTRADO") -> Rodolfo Sanchez | H8: GAC | I8: Produccion | P8: =SUM(P5:P7) -> 8275
B9: 45758 | C9: 3.5 mm 3205 Aqua 32% Proteina | D9: 3.52 | E9: =_xlfn.XLOOKUP(Table57618[[#This Row],[Descripcion]],Parametros!$B$3:$B$12,Parametros!$F$3:$F$12, "NO ENCONTRADO") -> 422.5 | F9: =D9*E9 -> 1487.2 | G9: =_xlfn.XLOOKUP(Table57618[[#This Row],[Descripcion]],Parametros!$B$3:$B$12,Parametros!$D$3:$D$12, "NO ENCONTRADO") -> Rodolfo Sanchez | H9: GAC | I9: Produccion
B10: 31/04/2025 | C10: 3.5 mm 3205 Aqua 32% Proteina | D10: 8.68 | E10: =_xlfn.XLOOKUP(Table57618[[#This Row],[Descripcion]],Parametros!$B$3:$B$12,Parametros!$F$3:$F$12, "NO ENCONTRADO") -> 422.5 | F10: =D10*E10 -> 3667.3 | G10: =_xlfn.XLOOKUP(Table57618[[#This Row],[Descripcion]],Parametros!$B$3:$B$12,Parametros!$D$3:$D$12, "NO ENCONTRADO") -> Rodolfo Sanchez | H10: GAC | I10: Produccion
B11: 45808 | C11: 3.5 mm 3205 Aqua 32% Proteina | D11: 6.24 | E11: =_xlfn.XLOOKUP(Table57618[[#This Row],[Descripcion]],Parametros!$B$3:$B$12,Parametros!$F$3:$F$12, "NO ENCONTRADO") -> 422.5 | F11: =D11*E11 -> 2636.4 | G11: =_xlfn.XLOOKUP(Table57618[[#This Row],[Descripcion]],Parametros!$B$3:$B$12,Parametros!$D$3:$D$12, "NO ENCONTRADO") -> Rodolfo Sanchez | H11: GAC | I11: Produccion
B12: 31/06/2025 | C12: 3.5 mm 3205 Aqua 32% Proteina | D12: 8.4 | E12: =_xlfn.XLOOKUP(Table57618[[#This Row],[Descripcion]],Parametros!$B$3:$B$12,Parametros!$F$3:$F$12, "NO ENCONTRADO") -> 422.5 | F12: =D12*E12 -> 3549 | G12: =_xlfn.XLOOKUP(Table57618[[#This Row],[Descripcion]],Parametros!$B$3:$B$12,Parametros!$D$3:$D$12, "NO ENCONTRADO") -> Rodolfo Sanchez | H12: GAC | I12: Produccion
B13: 45862 | C13: 3.5 mm 3205 Aqua 32% Proteina | D13: 7.56 | E13: =_xlfn.XLOOKUP(Table57618[[#This Row],[Descripcion]],Parametros!$B$3:$B$12,Parametros!$F$3:$F$12, "NO ENCONTRADO") -> 422.5 | F13: =D13*E13 -> 3194.1 | G13: =_xlfn.XLOOKUP(Table57618[[#This Row],[Descripcion]],Parametros!$B$3:$B$12,Parametros!$D$3:$D$12, "NO ENCONTRADO") -> Rodolfo Sanchez | H13: GAC | I13: Produccion
B14: 45877 | C14: 3.5 mm 3205 Aqua 32% Proteina | D14: 5 | E14: =_xlfn.XLOOKUP(Table57618[[#This Row],[Descripcion]],Parametros!$B$3:$B$12,Parametros!$F$3:$F$12, "NO ENCONTRADO") -> 422.5 | F14: =D14*E14 -> 2112.5 | G14: =_xlfn.XLOOKUP(Table57618[[#This Row],[Descripcion]],Parametros!$B$3:$B$12,Parametros!$D$3:$D$12, "NO ENCONTRADO") -> Rodolfo Sanchez | H14: GAC | I14: Produccion
B15: 45907 | C15: 5.0 mm 3005 Aqua 30% Proteina | D15: 15 | E15: =_xlfn.XLOOKUP(Table57618[[#This Row],[Descripcion]],Parametros!$B$3:$B$12,Parametros!$F$3:$F$12, "NO ENCONTRADO") -> 422.5 | F15: =D15*E15 -> 6337.5 | G15: =_xlfn.XLOOKUP(Table57618[[#This Row],[Descripcion]],Parametros!$B$3:$B$12,Parametros!$D$3:$D$12, "NO ENCONTRADO") -> Rodolfo Sanchez | H15: GAC | I15: Produccion
F16: =SUM(F5:F15) -> 39980.05
C18: INFORMACION RELEVANTE | F18: BIOMETRIAS | M18: INFORMACION RELEVANTE | P18: BIOMETRIAS | W18: INFORMACION RELEVANTE | Z18: BIOMETRIAS
C19: No. de Ciclo | D19: 1-2025 | F19: Fecha | G19: Promedio de Peso [Gr.] | H19: Dias Transcurridos | M19: No. de Ciclo | N19: 2-2025 | P19: Fecha | Q19: Promedio de Peso [Gr.] | R19: Dias Transcurridos | W19: No. de Ciclo | X19: 3-2025 | Z19: Fecha | AA19: Promedio de Peso [Gr.] | AB19: Dias Transcurridos
C20: Fecha de Ingreso | D20: 27/01/2025 | F20: 45684 | G20: 0.6 | H20: 0 | M20: Fecha de Ingreso | N20: 05/07/2025 | P20: 45843 | Q20: 0.7 | R20: 0 | W20: Fecha de Ingreso | X20: 08/08/2025 | Z20: 45877 | AA20: 2 | AB20: 0
C21: No. de Organismos | D21: 18500 | F21: 45735 | G21: 27 | H21: =_xlfn.DAYS(Table4919[[#This Row],[Fecha]],F20) -> 51 | M21: No. de Organismos | N21: 18950 | P21: 45874 | Q21: 7 | R21: =_xlfn.DAYS(P21,P20) -> 31 | W21: No. de Organismos | X21: 17000 | Z21: 45895 | AA21: 12.15 | AB21: =_xlfn.DAYS(Z21,Z20) -> 18
C22: Costo de compra por Organismo | D22: 0 | F22: 45754 | G22: 63 | H22: =_xlfn.DAYS(Table4919[[#This Row],[Fecha]],F21) -> 19 | M22: Costo de compra por Organismo | N22: 0 | P22: 45895 | Q22: 27 | R22: =_xlfn.DAYS(P22,P21) -> 21 | W22: Costo de compra por Organismo | X22: 0 | Z22: 45914 | AB22: =_xlfn.DAYS(Z22,Z21) -> 19
C23: Costo de Produccion Total | D23: =Table576[[#Totals],[Precio Total]] -> 50965.05 | F23: 45778 | G23: 83 | H23: =_xlfn.DAYS(Table4919[[#This Row],[Fecha]],F22) -> 24 | M23: Costo de Produccion Total | N23: =Table57610[[#Totals],[Precio Total]] -> 17622.5 | P23: 45914 | R23: =_xlfn.DAYS(P23,P22) -> 19 | W23: Costo de Produccion Total | X23: =Table5761014[[#Totals],[Precio Total]] -> 20812.5
C24: Costo de Produccion por Organismo | D24: =Table576[[#Totals],[Precio Total]]/D26 -> 10.19301 | F24: 45816 | G24: 99.4 | H24: =_xlfn.DAYS(Table4919[[#This Row],[Fecha]],F23) -> 38 | M24: Costo de Produccion por Organismo | N24: =Table57610[[#Totals],[Precio Total]]/N26 -> 0.92994723 | W24: Costo de Produccion por Organismo | X24: =Table5761014[[#Totals],[Precio Total]]/X26 -> 1.2242647
C25: Mortandad | D25: 13500 | F25: 45857 | G25: 182.4 | H25: =_xlfn.DAYS(Table4919[[#This Row],[Fecha]],F24) -> 41 | M25: Mortandad | N25: 0 | W25: Mortandad | X25: 0
C26: Organismos Aprovechados | D26: =D21-D25 -> 5000 | F26: 45874 | G26: 237 | H26: =_xlfn.DAYS(Table4919[[#This Row],[Fecha]],F25) -> 17 | M26: Organismos Aprovechados | N26: =N21-N25 -> 18950 | W26: Organismos Aprovechados | X26: =X21-X25 -> 17000
C27: Participacion por Organismo | D27: =100/D21 -> 0.0054054054 | F27: 45882 | G27: 282 | H27: =_xlfn.DAYS(Table4919[[#This Row],[Fecha]],F26) -> 8 | M27: Participacion por Organismo | N27: =100/N21 -> 0.0052770449 | W27: Participacion por Organismo | X27: =100/X21 -> 0.0058823529
C28: Ventas Realizadas | D28: =Table9148[[#Totals],[Fecha]] -> 9 | M28: Ventas Realizadas | N28: =Table914812[[#Totals],[Fecha]] -> 2 | W28: Ventas Realizadas | X28: =Table91481216[[#Totals],[Fecha]] -> 0
C29: Organismos Restantes | D29: =D26-D28 -> 4991 | M29: Organismos Restantes | N29: =N26-N28 -> 18948 | W29: Organismos Restantes | X29: =X26-X28 -> 17000
C30: Biomasa Vendida | D30: =Table9148[[#Totals],[Peso del Organismo]] -> 636.09 | M30: Biomasa Vendida | N30: =Table914812[[#Totals],[Peso del Organismo]] -> 261.75 | W30: Biomasa Vendida | X30: =Table91481216[[#Totals],[Peso del Organismo]] -> 0
C31: Promedio de Peso | D31: =D30/D28 -> 70.676667 | M31: Promedio de Peso | N31: =N30/N28 -> 130.875 | W31: Promedio de Peso | X31: =X30/X28 -> #DIV/0!
C32: Fecha Actualizada | D32: 13/09/2025 | M32: Fecha Actualizada | N32: 13/09/2025 | W32: Fecha Actualizada | X32: 13/09/2025
C33: Dias Transcurridos del Ciclo | D33: =D32-D20 -> 229 | M33: Dias Transcurridos del Ciclo | N33: =N32-N20 -> 70 | W33: Dias Transcurridos del Ciclo | X33: =X32-X20 -> 36

Sheet Sheet2
B2: Dias | C2: Costo de Alevines | D2: Renta de Estanque | E2: Renta de Aereadores | F2: Mano de Obra | R2: Biomasa
B3: 1 | C3: 18500 | D3: 100 | E3: 0 | F3: 350 | P3: 1 | Q3: 0.3 - 52% Proteina | R3: =(18500*P3)/1000 -> 18.5 | S3: 0.1
B4: 2 | D4: 100 | E4: 0 | F4: 350 | P4: =P3+0.571428571428571 -> 1.5714286 | Q4: 0.3 - 52% Proteina | R4: =(18500*P4)/1000 -> 29.071429 | S4: 0.1
B5: 3 | D5: 100 | E5: 0 | F5: 350 | P5: =P4+0.571428571428571 -> 2.1428571 | Q5: 0.3 - 52% Proteina | R5: =(18500*P5)/1000 -> 39.642857 | S5: 0.1
B6: 4 | D6: 100 | E6: 0 | F6: 350 | P6: =P5+0.571428571428571 -> 2.7142857 | Q6: 0.3 - 52% Proteina | R6: =(18500*P6)/1000 -> 50.214286 | S6: 0.1
B7: 5 | D7: 100 | E7: 0 | F7: 350 | P7: =P6+0.571428571428571 -> 3.2857143 | Q7: 0.3 - 52% Proteina | R7: =(18500*P7)/1000 -> 60.785714 | S7: 0.1
B8: 6 | D8: 100 | E8: 0 | F8: 350 | P8: =P7+0.571428571428571 -> 3.8571429 | Q8: 0.3 - 52% Proteina | R8: =(18500*P8)/1000 -> 71.357143 | S8: 0.1
B9: 7 | D9: 100 | E9: 0 | F9: 350 | P9: =P8+0.571428571428571 -> 4.4285714 | Q9: 0.3 - 52% Proteina | R9: =(18500*P9)/1000 -> 81.928571 | S9: 0.1
B10: 8 | D10: 100 | E10: 0 | F10: 350 | P10: =P9+0.571428571428571 -> 5 | Q10: 0.3 - 52% Proteina | R10: =(18500*P10)/1000 -> 92.5 | S10: 0.09
B11: 9 | D11: 100 | E11: 0 | F11: 350 | P11: =P10+0.714285714285714 -> 5.7142857 | Q11: 0.3 - 52% Proteina | R11: =(18500*P11)/1000 -> 105.71429 | S11: 0.09
B12: 10 | D12: 100 | E12: 0 | F12: 350 | P12: =P11+0.714285714285714 -> 6.4285714 | Q12: 0.3 - 52% Proteina | R12: =(18500*P12)/1000 -> 118.92857 | S12: 0.09
B13: 11 | D13: 100 | E13: 0 | F13: 350 | P13: =P12+0.714285714285714 -> 7.1428571 | Q13: 0.3 - 52% Proteina | R13: =(18500*P13)/1000 -> 132.14286 | S13: 0.09
B14: 12 | D14: 100 | E14: 0 | F14: 350 | P14: =P13+0.714285714285714 -> 7.8571429 | Q14: 0.3 - 52% Proteina | R14: =(18500*P14)/1000 -> 145.35714 | S14: 0.09
B15: 13 | D15: 100 | E15: 0 | F15: 350 | P15: =P14+0.714285714285714 -> 8.5714286 | Q15: 0.3 - 52% Proteina | R15: =(18500*P15)/1000 -> 158.57143 | S15: 0.08
B16: 14 | D16: 100 | E16: 0 | F16: 350 | P16: =P15+0.714285714285714 -> 9.2857143 | Q16: 0.3 - 52% Proteina | R16: =(18500*P16)/1000 -> 171.78571 | S16: 0.08
B17: 15 | D17: 100 | E17: 0 | F17: 350 | P17: =P16+0.714285714285714 -> 10 | Q17: 1.5 - 45% Proteina | R17: =(18500*P17)/1000 -> 185 | S17: 0.08
B18: 16 | D18: 100 | E18: 0 | F18: 350 | P18: =P17+0.714285714285714 -> 10.714286 | Q18: 1.5 - 45% Proteina | R18: =(18500*P18)/1000 -> 198.21429 | S18: 0.08
B19: 17 | D19: 100 | E19: 0 | F19: 350 | P19: =P18+0.714285714285714 -> 11.428571 | Q19: 1.5 - 45% Proteina | R19: =(18500*P19)/1000 -> 211.42857 | S19: 0.08
B20: 18 | D20: 100 | E20: 0 | F20: 350 | P20: =P19+0.714285714285714 -> 12.142857 | Q20: 1.5 - 45% Proteina | R20: =(18500*P20)/1000 -> 224.64286 | S20: 0.08
B21: 19 | D21: 100 | E21: 0 | F21: 350 | P21: =P20+0.714285714285714 -> 12.857143 | Q21: 1.5 - 45% Proteina | R21: =(18500*P21)/1000 -> 237.85714 | S21: 0.08
B22: 20 | D22: 100 | E22: 0 | F22: 350 | P22: =P21+0.714285714285714 -> 13.571429 | Q22: 1.5 - 45% Proteina | R22: =(18500*P22)/1000 -> 251.07143 | S22: 0.08
... B31: 29 | D31: 100 | E31: 0 | F31: 350 | P31: =P30+0.714285714285714 -> 20 | Q31: 2.5 - 45% Proteina | R31: =(18500*P31)/1000 -> 370 | S31: 0.08
B32: 30 | D32: 100 | E32: 0 | F32: 350 | P32: =P31+1.42857142857142 -> 21.428571 | Q32: 2.5 - 45% Proteina | R32: =(18000*P32)/1000 -> 385.71429 | S32: 0.08
B33: 31 | D33: 100 | E33: 0 | F33: 350 | P33: =P32+1.42857142857142 -> 22.857143 | Q33: 2.5 - 45% Proteina | R33: =(18000*P33)/1000 -> 411.42857 | S33: 0.08
B34: 32 | D34: 100 | E34: 0 | F34: 350 | P34: =P33+1.42857142857142 -> 24.285714 | Q34: 2.5 - 45% Proteina | R34: =(18000*P34)/1000 -> 437.14286 | S34: 0.08
B35: 33 | D35: 100 | E35: 0 | F35: 350 | P35: =P34+1.42857142857142 -> 25.714286 | Q35: 2.5 - 45% Proteina | R35: =(18000*P35)/1000 -> 462.85714 | S35: 0.08
B36: 34 | D36: 100 | E36: 0 | F36: 350 | P36: =P35+1.42857142857142 -> 27.142857 | Q36: 2.5 - 45% Proteina | R36: =(18000*P36)/1000 -> 488.57143 | S36: 0.08
B37: 35 | D37: 100 | E37: 0 | F37: 350 | P37: =P36+1.42857142857142 -> 28.571429 | Q37: 2.5 - 45% Proteina | R37: =(18000*P37)/1000 -> 514.28571 | S37: 0.08
B38: 36 | D38: 100 | E38: 0 | F38: 350 | P38: =P37+1.42857142857142 -> 30 | Q38: 2.5 - 45% Proteina | R38: =(18000*P38)/1000 -> 540 | S38: 0.08
B39: 37 | D39: 100 | E39: 0 | F39: 350 | P39: =P38+3.57142857142857 -> 33.571429 | Q39: 2.5 - 45% Proteina | R39: =(18000*P39)/1000 -> 604.28571 | S39: 0.07
B40: 38 | D40: 100 | E40: 0 | F40: 350 | P40: =P39+3.57142857142857 -> 37.142857 | Q40: 2.5 - 45% Proteina | R40: =(18000*P40)/1000 -> 668.57143 | S40: 0.07
B41: 39 | D41: 100 | E41: 0 | F41: 350 | P41: =P40+3.57142857142857 -> 40.714286 | Q41: 2.5 - 45% Proteina | R41: =(18000*P41)/1000 -> 732.85714 | S41: 0.07
B42: 40 | D42: 100 | E42: 0 | F42: 350 | P42: =P41+3.57142857142857 -> 44.285714 | Q42: 2.5 - 45% Proteina | R42: =(18000*P42)/1000 -> 797.14286 | S42: 0.07
B43: 41 | D43: 100 | E43: 0 | F43: 350 | P43: =P42+3.57142857142857 -> 47.857143 | Q43: 2.5 - 45% Proteina | R43: =(18000*P43)/1000 -> 861.42857 | S43: 0.07
B44: 42 | D44: 100 | E44: 0 | F44: 350 | P44: =P43+3.57142857142857 -> 51.428571 | Q44: 2.5 - 45% Proteina | R44: =(18000*P44)/1000 -> 925.71429 | S44: 0.07
B45: 43 | D45: 100 | E45: 50 | F45: 350 | P45: =P44+3.57142857142857 -> 55 | Q45: 2.5 - 45% Proteina | R45: =(18000*P45)/1000 -> 990 | S45: 0.06
B46: 44 | D46: 100 | E46: 50 | F46: 350 | P46: =P45+3.57142857142857 -> 58.571429 | Q46: 2.5 - 45% Proteina | R46: =(18000*P46)/1000 -> 1054.2857 | S46: 0.06
B47: 45 | D47: 100 | E47: 50 | F47: 350 | P47: =P46+3.57142857142857 -> 62.142857 | Q47: 2.5 - 45% Proteina | R47: =(18000*P47)/1000 -> 1118.5714 | S47: 0.06
B48: 46 | D48: 100 | E48: 50 | F48: 350 | P48: =P47+3.57142857142857 -> 65.714286 | Q48: 2.5 - 45% Proteina | R48: =(18000*P48)/1000 -> 1182.8571 | S48: 0.06
B49: 47 | D49: 100 | E49: 50 | F49: 350 | P49: =P48+3.57142857142857 -> 69.285714 | Q49: 2.5 - 45% Proteina | R49: =(18000*P49)/1000 -> 1247.1429 | S49: 0.06
...
