Workbook

Sheet Tesoreria Overview
B1: #VALUE! | C1: SEGUIMIENTO DE TESORERIA
C2: ENERO | D2: FEBRERO | E2: MARZO | F2: ABRIL | G2: MAYO | H2: JUNIO | I2: JULIO | J2: AGOSTO | K2: SEPTIEMBRE | L2: OCTUBRE | M2: NOVIEMBRE | N2: DICIEMBRE
B3: Saldo inicial [Saldo en cuenta] | C3: 0 | D3: =C9 -> -12371.88 | E3: =D9 -> -32785.03 | F3: =E9 -> -51579.18 | G3: =F9 -> -50114.18 | H3: =G9 -> -73180.32 | I3: =H9 -> -63676.84 | J3: =I9 -> 22632.98 | K3: =J9 -> 25447.944 | ... N3: =M9 -> 126673.11
B4: Ingresos totales | C4: =C24 -> 22044 | D4: =D24 -> 16168 | E4: =E24 -> 53520 | F4: =F24 -> 32210 | G4: =G24 -> 12675 | H4: =H24 -> 43615 | I4: =I24 -> 132200 | J4: =J24 -> 85832.5 | ... N4: =N24 -> 0 | O4: =SUM(C4:N4) -> 568989.5
B5: Ingresos Estimados | C5: =Estimado!C22+C31 -> 0 | D5: =Estimado!D22+D31 -> 0 | E5: =Estimado!E22+E31 -> 0 | F5: =Estimado!F22+F31 -> 0 | G5: =Estimado!G22+G31 -> 0 | H5: =Estimado!H22+H31 -> 0 | I5: =Estimado!I22+I31 -> 0 | J5: =Estimado!J22+J31 -> 4000 | ... N5: =Estimado!N22+N31 -> 0 | O5: =SUM(C5:N5) -> 150610
B6: Egresos Totales | C6: =C95 -> 34415.88 | D6: =D95 -> 36581.15 | E6: =E95 -> 72314.15 | F6: =F95 -> 30745 | G6: =G95 -> 35741.14 | H6: =H95 -> 34111.52 | I6: =I95 -> 45890.18 | J6: =J95 -> 83017.536 | ... N6: =N95 -> 0 | O6: =SUM(C6:N6) -> 442316.39
B7: Egresos Estimados | C7: =Estimado!C74 -> 0 | D7: =Estimado!D74 -> 0 | E7: =Estimado!E74 -> 0 | F7: =Estimado!F74 -> 0 | G7: =Estimado!G74 -> 0 | H7: =Estimado!H74 -> 0 | I7: =Estimado!I74 -> 0 | J7: =Estimado!J74 -> 0 | ... N7: =Estimado!N74 -> 0 | O7: =SUM(C7:N7) -> 0
B8: INGRESOS NETOS | C8: =C4-C6 -> -12371.88 | D8: =D4-D6 -> -20413.15 | E8: =E4-E6 -> -18794.15 | F8: =F4-F6 -> 1465 | G8: =G4-G6 -> -23066.14 | H8: =H4-H6 -> 9503.48 | I8: =I4-I6 -> 86309.82 | J8: =J4-J6 -> 2814.9638 | ... N8: =N4-N6 -> 0 | O8: =SUM(C8:N8) -> 126673.11
B9: Saldo final proyectado | C9: =C4-C6+C3 -> -12371.88 | D9: =D4-D6+D3 -> -32785.03 | E9: =E4-E6+E3 -> -51579.18 | F9: =F4-F6+F3 -> -50114.18 | G9: =G4-G6+G3 -> -73180.32 | H9: =H4-H6+H3 -> -63676.84 | I9: =I4-I6+I3 -> 22632.98 | J9: =J4-J6+J3 -> 25447.944 | ... N9: =N4-N6+N3 -> 126673.11
B11: INGRESOS
B13: Venta de Alevines | C13: =SUMIF(Enero_2024[CATEGORÍA],$B13,Enero_2024[INGRESO]) -> 22044 | D13: =SUMIF(Febrero_2024[CATEGORÍA],$B13,Febrero_2024[INGRESO]) -> 15818 | E13: =SUMIF(Marzo_2024[CATEGORÍA],$B13,Marzo_2024[INGRESO]) -> 53120 | F13: =SUMIF(Abril_2024[CATEGORÍA],$B13,Abril_2024[INGRESO]) -> 32080 | G13: =SUMIF(Mayo_2024[CATEGORÍA],$B13,Mayo_2024[INGRESO]) -> 12675 | H13: =SUMIF(Junio_2024[CATEGORÍA],$B13,Junio_2024[INGRESO]) -> 43615 | I13: =SUMIF(Julio_2024[CATEGORÍA],$B13,Julio_2024[INGRESO]) -> 132200 | J13: =SUMIF(Agosto_2024[CATEGORÍA],$B13,Agosto_2024[INGRESO]) -> 84997.5 | K13: =SUMIF(Septiembre_2024[CATEGORÍA],$B13,Septiembre_2024[INGRESO]) -> 99340 | L13: =SUMIF(Octubre_2024[CATEGORÍA],$B13,Octubre_2024[INGRESO]) -> 66120 | M13: =SUMIF(Noviembre_2024[CATEGORÍA],$B13,Noviembre_2024[INGRESO]) -> 0 | N13: =SUMIF(Diciembre_2024[CATEGORÍA],$B13,Diciembre_2024[INGRESO]) -> 0 | O13: =SUM(D13:N13) -> 539965.5
B14: Venta de Mojarras (Kg) | C14: =SUMIF(Enero_2024[CATEGORÍA],$B14,Enero_2024[INGRESO]) -> 0 | D14: =SUMIF(Febrero_2024[CATEGORÍA],$B14,Febrero_2024[INGRESO]) -> 0 | E14: =SUMIF(Marzo_2024[CATEGORÍA],$B14,Marzo_2024[INGRESO]) -> 0 | F14: =SUMIF(Abril_2024[CATEGORÍA],$B14,Abril_2024[INGRESO]) -> 0 | G14: =SUMIF(Mayo_2024[CATEGORÍA],$B14,Mayo_2024[INGRESO]) -> 0 | H14: =SUMIF(Junio_2024[CATEGORÍA],$B14,Junio_2024[INGRESO]) -> 0 | I14: =SUMIF(Julio_2024[CATEGORÍA],$B14,Julio_2024[INGRESO]) -> 0 | J14: =SUMIF(Agosto_2024[CATEGORÍA],$B14,Agosto_2024[INGRESO]) -> 0 | K14: =SUMIF(Septiembre_2024[CATEGORÍA],$B14,Septiembre_2024[INGRESO]) -> 0 | L14: =SUMIF(Octubre_2024[CATEGORÍA],$B14,Octubre_2024[INGRESO]) -> 0 | M14: =SUMIF(Noviembre_2024[CATEGORÍA],$B14,Noviembre_2024[INGRESO]) -> 0 | N14: =SUMIF(Diciembre_2024[CATEGORÍA],$B14,Diciembre_2024[INGRESO]) -> 0 | O14: =SUM(D14:N14) -> 0
B15: Venta de Alimento | C15: =SUMIF(Enero_2024[CATEGORÍA],$B15,Enero_2024[INGRESO]) -> 0 | D15: =SUMIF(Febrero_2024[CATEGORÍA],$B15,Febrero_2024[INGRESO]) -> 350 | E15: =SUMIF(Marzo_2024[CATEGORÍA],$B15,Marzo_2024[INGRESO]) -> 400 | F15: =SUMIF(Abril_2024[CATEGORÍA],$B15,Abril_2024[INGRESO]) -> 130 | G15: =SUMIF(Mayo_2024[CATEGORÍA],$B15,Mayo_2024[INGRESO]) -> 0 | H15: =SUMIF(Junio_2024[CATEGORÍA],$B15,Junio_2024[INGRESO]) -> 0 | I15: =SUMIF(Julio_2024[CATEGORÍA],$B15,Julio_2024[INGRESO]) -> 0 | J15: =SUMIF(Agosto_2024[CATEGORÍA],$B15,Agosto_2024[INGRESO]) -> 835 | K15: =SUMIF(Septiembre_2024[CATEGORÍA],$B15,Septiembre_2024[INGRESO]) -> 5265 | L15: =SUMIF(Octubre_2024[CATEGORÍA],$B15,Octubre_2024[INGRESO]) -> 0 | M15: =SUMIF(Noviembre_2024[CATEGORÍA],$B15,Noviembre_2024[INGRESO]) -> 0 | N15: =SUMIF(Diciembre_2024[CATEGORÍA],$B15,Diciembre_2024[INGRESO]) -> 0 | O15: =SUM(D15:N15) -> 6980
B16: Venta Medicamentos/Vitaminas | C16: =SUMIF(Enero_2024[CATEGORÍA],$B16,Enero_2024[INGRESO]) -> 0 | D16: =SUMIF(Febrero_2024[CATEGORÍA],$B16,Febrero_2024[INGRESO]) -> 0 | E16: =SUMIF(Marzo_2024[CATEGORÍA],$B16,Marzo_2024[INGRESO]) -> 0 | F16: =SUMIF(Abril_2024[CATEGORÍA],$B16,Abril_2024[INGRESO]) -> 0 | G16: =SUMIF(Mayo_2024[CATEGORÍA],$B16,Mayo_2024[INGRESO]) -> 0 | H16: =SUMIF(Junio_2024[CATEGORÍA],$B16,Junio_2024[INGRESO]) -> 0 | I16: =SUMIF(Julio_2024[CATEGORÍA],$B16,Julio_2024[INGRESO]) -> 0 | J16: =SUMIF(Agosto_2024[CATEGORÍA],$B16,Agosto_2024[INGRESO]) -> 0 | K16: =SUMIF(Septiembre_2024[CATEGORÍA],$B16,Septiembre_2024[INGRESO]) -> 0 | L16: =SUMIF(Octubre_2024[CATEGORÍA],$B16,Octubre_2024[INGRESO]) -> 0 | M16: =SUMIF(Noviembre_2024[CATEGORÍA],$B16,Noviembre_2024[INGRESO]) -> 0 | N16: =SUMIF(Diciembre_2024[CATEGORÍA],$B16,Diciembre_2024[INGRESO]) -> 0 | O16: =SUM(D16:N16) -> 0
B17: Ingresos por intereses | C17: =SUMIF(Enero_2024[CATEGORÍA],$B17,Enero_2024[INGRESO]) -> 0 | D17: =SUMIF(Febrero_2024[CATEGORÍA],$B17,Febrero_2024[INGRESO]) -> 0 | E17: =SUMIF(Marzo_2024[CATEGORÍA],$B17,Marzo_2024[INGRESO]) -> 0 | F17: =SUMIF(Abril_2024[CATEGORÍA],$B17,Abril_2024[INGRESO]) -> 0 | G17: =SUMIF(Mayo_2024[CATEGORÍA],$B17,Mayo_2024[INGRESO]) -> 0 | H17: =SUMIF(Junio_2024[CATEGORÍA],$B17,Junio_2024[INGRESO]) -> 0 | I17: =SUMIF(Julio_2024[CATEGORÍA],$B17,Julio_2024[INGRESO]) -> 0 | J17: =SUMIF(Agosto_2024[CATEGORÍA],$B17,Agosto_2024[INGRESO]) -> 0 | K17: =SUMIF(Septiembre_2024[CATEGORÍA],$B17,Septiembre_2024[INGRESO]) -> 0 | L17: =SUMIF(Octubre_2024[CATEGORÍA],$B17,Octubre_2024[INGRESO]) -> 0 | M17: =SUMIF(Noviembre_2024[CATEGORÍA],$B17,Noviembre_2024[INGRESO]) -> 0 | N17: =SUMIF(Diciembre_2024[CATEGORÍA],$B17,Diciembre_2024[INGRESO]) -> 0 | O17: =SUM(D17:N17) -> 0
B18: Servicios de Gestion | C18: =SUMIF(Enero_2024[CATEGORÍA],$B18,Enero_2024[INGRESO]) -> 0 | D18: =SUMIF(Febrero_2024[CATEGORÍA],$B18,Febrero_2024[INGRESO]) -> 0 | E18: =SUMIF(Marzo_2024[CATEGORÍA],$B18,Marzo_2024[INGRESO]) -> 0 | F18: =SUMIF(Abril_2024[CATEGORÍA],$B18,Abril_2024[INGRESO]) -> 0 | G18: =SUMIF(Mayo_2024[CATEGORÍA],$B18,Mayo_2024[INGRESO]) -> 0 | H18: =SUMIF(Junio_2024[CATEGORÍA],$B18,Junio_2024[INGRESO]) -> 0 | I18: =SUMIF(Julio_2024[CATEGORÍA],$B18,Julio_2024[INGRESO]) -> 0 | J18: =SUMIF(Agosto_2024[CATEGORÍA],$B18,Agosto_2024[INGRESO]) -> 0 | K18: =SUMIF(Septiembre_2024[CATEGORÍA],$B18,Septiembre_2024[INGRESO]) -> 0 | L18: =SUMIF(Octubre_2024[CATEGORÍA],$B18,Octubre_2024[INGRESO]) -> 0 | M18: =SUMIF(Noviembre_2024[CATEGORÍA],$B18,Noviembre_2024[INGRESO]) -> 0 | N18: =SUMIF(Diciembre_2024[CATEGORÍA],$B18,Diciembre_2024[INGRESO]) -> 0 | O18: =SUM(D18:N18) -> 0
B19: Reembolsos | C19: =SUMIF(Enero_2024[CATEGORÍA],$B19,Enero_2024[INGRESO]) -> 0 | D19: =SUMIF(Febrero_2024[CATEGORÍA],$B19,Febrero_2024[INGRESO]) -> 0 | E19: =SUMIF(Marzo_2024[CATEGORÍA],$B19,Marzo_2024[INGRESO]) -> 0 | F19: =SUMIF(Abril_2024[CATEGORÍA],$B19,Abril_2024[INGRESO]) -> 0 | G19: =SUMIF(Mayo_2024[CATEGORÍA],$B19,Mayo_2024[INGRESO]) -> 0 | H19: =SUMIF(Junio_2024[CATEGORÍA],$B19,Junio_2024[INGRESO]) -> 0 | I19: =SUMIF(Julio_2024[CATEGORÍA],$B19,Julio_2024[INGRESO]) -> 0 | J19: =SUMIF(Agosto_2024[CATEGORÍA],$B19,Agosto_2024[INGRESO]) -> 0 | K19: =SUMIF(Septiembre_2024[CATEGORÍA],$B19,Septiembre_2024[INGRESO]) -> 0 | L19: =SUMIF(Octubre_2024[CATEGORÍA],$B19,Octubre_2024[INGRESO]) -> 0 | M19: =SUMIF(Noviembre_2024[CATEGORÍA],$B19,Noviembre_2024[INGRESO]) -> 0 | N19: =SUMIF(Diciembre_2024[CATEGORÍA],$B19,Diciembre_2024[INGRESO]) -> 0 | O19: =SUM(D19:N19) -> 0
B20: Comisiones | C20: =SUMIF(Enero_2024[CATEGORÍA],$B20,Enero_2024[INGRESO]) -> 0 | D20: =SUMIF(Febrero_2024[CATEGORÍA],$B20,Febrero_2024[INGRESO]) -> 0 | E20: =SUMIF(Marzo_2024[CATEGORÍA],$B20,Marzo_2024[INGRESO]) -> 0 | F20: =SUMIF(Abril_2024[CATEGORÍA],$B20,Abril_2024[INGRESO]) -> 0 | G20: =SUMIF(Mayo_2024[CATEGORÍA],$B20,Mayo_2024[INGRESO]) -> 0 | H20: =SUMIF(Junio_2024[CATEGORÍA],$B20,Junio_2024[INGRESO]) -> 0 | I20: =SUMIF(Julio_2024[CATEGORÍA],$B20,Julio_2024[INGRESO]) -> 0 | J20: =SUMIF(Agosto_2024[CATEGORÍA],$B20,Agosto_2024[INGRESO]) -> 0 | K20: =SUMIF(Septiembre_2024[CATEGORÍA],$B20,Septiembre_2024[INGRESO]) -> 0 | L20: =SUMIF(Octubre_2024[CATEGORÍA],$B20,Octubre_2024[INGRESO]) -> 0 | M20: =SUMIF(Noviembre_2024[CATEGORÍA],$B20,Noviembre_2024[INGRESO]) -> 0 | N20: =SUMIF(Diciembre_2024[CATEGORÍA],$B20,Diciembre_2024[INGRESO]) -> 0 | O20: =SUM(D20:N20) -> 0
B21: Fondeo Externo y Pasivos | C21: =SUMIF(Enero_2024[CATEGORÍA],$B21,Enero_2024[INGRESO]) -> 0 | D21: =SUMIF(Febrero_2024[CATEGORÍA],$B21,Febrero_2024[INGRESO]) -> 0 | E21: =SUMIF(Marzo_2024[CATEGORÍA],$B21,Marzo_2024[INGRESO]) -> 0 | F21: =SUMIF(Abril_2024[CATEGORÍA],$B21,Abril_2024[INGRESO]) -> 0 | G21: =SUMIF(Mayo_2024[CATEGORÍA],$B21,Mayo_2024[INGRESO]) -> 0 | H21: =SUMIF(Junio_2024[CATEGORÍA],$B21,Junio_2024[INGRESO]) -> 0 | I21: =SUMIF(Julio_2024[CATEGORÍA],$B21,Julio_2024[INGRESO]) -> 0 | J21: =SUMIF(Agosto_2024[CATEGORÍA],$B21,Agosto_2024[INGRESO]) -> 0 | K21: =SUMIF(Septiembre_2024[CATEGORÍA],$B21,Septiembre_2024[INGRESO]) -> 0 | L21: =SUMIF(Octubre_2024[CATEGORÍA],$B21,Octubre_2024[INGRESO]) -> 0 | M21: =SUMIF(Noviembre_2024[CATEGORÍA],$B21,Noviembre_2024[INGRESO]) -> 0 | N21: =SUMIF(Diciembre_2024[CATEGORÍA],$B21,Diciembre_2024[INGRESO]) -> 0 | O21: =SUM(D21:N21) -> 0
B22: Miscelaneo | C22: =SUMIF(Enero_2024[CATEGORÍA],$B22,Enero_2024[INGRESO]) -> 0 | D22: =SUMIF(Febrero_2024[CATEGORÍA],$B22,Febrero_2024[INGRESO]) -> 0 | E22: =SUMIF(Marzo_2024[CATEGORÍA],$B22,Marzo_2024[INGRESO]) -> 0 | F22: =SUMIF(Abril_2024[CATEGORÍA],$B22,Abril_2024[INGRESO]) -> 0 | G22: =SUMIF(Mayo_2024[CATEGORÍA],$B22,Mayo_2024[INGRESO]) -> 0 | H22: =SUMIF(Junio_2024[CATEGORÍA],$B22,Junio_2024[INGRESO]) -> 0 | I22: =SUMIF(Julio_2024[CATEGORÍA],$B22,Julio_2024[INGRESO]) -> 0 | J22: =SUMIF(Agosto_2024[CATEGORÍA],$B22,Agosto_2024[INGRESO]) -> 0 | K22: =SUMIF(Septiembre_2024[CATEGORÍA],$B22,Septiembre_2024[INGRESO]) -> 0 | L22: =SUMIF(Octubre_2024[CATEGORÍA],$B22,Octubre_2024[INGRESO]) -> 0 | M22: =SUMIF(Noviembre_2024[CATEGORÍA],$B22,Noviembre_2024[INGRESO]) -> 0 | N22: =SUMIF(Diciembre_2024[CATEGORÍA],$B22,Diciembre_2024[INGRESO]) -> 0 | O22: =SUM(D22:N22) -> 0
B24: TOTAL | C24: =SUM(C13:C22) -> 22044 | D24: =SUM(D13:D22) -> 16168 | E24: =SUM(E13:E22) -> 53520 | F24: =SUM(F13:F22) -> 32210 | G24: =SUM(G13:G22) -> 12675 | H24: =SUM(H13:H22) -> 43615 | I24: =SUM(I13:I22) -> 132200 | J24: =SUM(J13:J22) -> 85832.5 | ... O24: =SUM(O13:O22) -> 546945.5
B26: CAPITAL
B28: Fondo Liquido | C28: =SUMIF(Enero_2024[CATEGORÍA],$B28,Enero_2024[INGRESO]) -> 0 | D28: =SUMIF(Febrero_2024[CATEGORÍA],$B28,Febrero_2024[INGRESO]) -> 0 | E28: =SUMIF(Marzo_2024[CATEGORÍA],$B28,Marzo_2024[INGRESO]) -> 0 | F28: =SUMIF(Abril_2024[CATEGORÍA],$B28,Abril_2024[INGRESO]) -> 0 | G28: =SUMIF(Mayo_2024[CATEGORÍA],$B28,Mayo_2024[INGRESO]) -> 0 | H28: =SUMIF(Junio_2024[CATEGORÍA],$B28,Junio_2024[INGRESO]) -> 0 | I28: =SUMIF(Julio_2024[CATEGORÍA],$B28,Julio_2024[INGRESO]) -> 0 | J28: =SUMIF(Agosto_2024[CATEGORÍA],$B28,Agosto_2024[INGRESO]) -> 0 | K28: =SUMIF(Septiembre_2024[CATEGORÍA],$B28,Septiembre_2024[INGRESO]) -> 0 | L28: =SUMIF(Octubre_2024[CATEGORÍA],$B28,Octubre_2024[INGRESO]) -> 0 | M28: =SUMIF(Noviembre_2024[CATEGORÍA],$B28,Noviembre_2024[INGRESO]) -> 0 | N28: =SUMIF(Diciembre_2024[CATEGORÍA],$B28,Diciembre_2024[INGRESO]) -> 0 | O28: =SUM(D28:N28) -> 0
B29: Capital en Caja de Ahorro | C29: =C41 -> 2600 | D29: =C29+D41 -> 5800 | E29: =D29+E41 -> 10200 | F29: =E29+F41 -> 13400 | G29: =F29+G41 -> 16600 | H29: =G29+H41 -> 19600 | I29: =H29+I41 -> 22800 | J29: =I29+J41 -> 27600 | K29: =J29+K41 -> 30800 | ... N29: =M29+N41 -> 30800 | O29: =SUM(D29:N29) -> 239200
B30: Intereses Caja de Ahorro | C30: =SUMIF(Enero_2024[CATEGORÍA],$B30,Enero_2024[INGRESO]) -> 0 | D30: =SUMIF(Febrero_2024[CATEGORÍA],$B30,Febrero_2024[INGRESO])+C30 -> 0 | E30: =SUMIF(Febrero_2024[SUB CATEGORIA],$B30,Febrero_2024[EGRESO])+D30 -> 0 | F30: =SUMIF(Febrero_2024[EQUILIBRAR],$B30,Febrero_2024[BENEFICIARIO/PROVEEDOR])+E30 -> 0 | G30: =SUMIF(Febrero_2024[CUENTA],$B30,Febrero_2024[NO. FACTURA])+F30 -> 0 | H30: =SUMIF(Febrero_2024[FECHA],$B30,Febrero_2024[NO. PROYECTO])+G30 -> 0 | I30: =SUMIF(Febrero_2024[INGRESO],$B30,Febrero_2024[DESCRIPCION])+H30 -> 0 | J30: =SUMIF(Febrero_2024[EGRESO],$B30,Febrero_2024[CATEGORÍA])+I30 -> 0 | K30: =SUMIF(Febrero_2024[BENEFICIARIO/PROVEEDOR],$B30,Febrero_2024[SUB CATEGORIA])+J30 -> 0 | L30: =SUMIF(Febrero_2024[NO. FACTURA],$B30,Febrero_2024[EQUILIBRAR])+K30 -> 0 | M30: =SUMIF(Febrero_2024[NO. PROYECTO],$B30,Febrero_2024[CUENTA])+L30 -> 0 | N30: =SUMIF(Febrero_2024[DESCRIPCION],$B30,Febrero_2024[FECHA])+M30 -> 0
B31: Cuentas por Cobrar | C31: =SUMIF(Enero_2024[CATEGORÍA],$B31,Enero_2024[INGRESO]) -> 0 | D31: =SUMIF(Febrero_2024[CATEGORÍA],$B31,Febrero_2024[INGRESO]) -> 0 | E31: =SUMIF(Marzo_2024[CATEGORÍA],$B31,Marzo_2024[INGRESO]) -> 0 | F31: =SUMIF(Abril_2024[CATEGORÍA],$B31,Abril_2024[INGRESO]) -> 0 | G31: =SUMIF(Mayo_2024[CATEGORÍA],$B31,Mayo_2024[INGRESO]) -> 0 | H31: =SUMIF(Junio_2024[CATEGORÍA],$B31,Junio_2024[INGRESO]) -> 0 | I31: =SUMIF(Julio_2024[CATEGORÍA],$B31,Julio_2024[INGRESO]) -> 0 | J31: =SUMIF(Agosto_2024[CATEGORÍA],$B31,Agosto_2024[INGRESO]) -> 4000 | K31: =SUMIF(Septiembre_2024[CATEGORÍA],$B31,Septiembre_2024[INGRESO]) -> 0 | L31: =SUMIF(Octubre_2024[CATEGORÍA],$B31,Octubre_2024[INGRESO]) -> 0 | M31: =SUMIF(Noviembre_2024[CATEGORÍA],$B31,Noviembre_2024[INGRESO]) -> 146610 | N31: =SUMIF(Diciembre_2024[CATEGORÍA],$B31,Diciembre_2024[INGRESO]) -> 0 | O31: =SUM(D31:N31) -> 150610
B32: Otro | C32: =SUMIF(Enero_2024[CATEGORÍA],$B32,Enero_2024[INGRESO]) -> 0 | D32: =SUMIF(Febrero_2024[CATEGORÍA],$B32,Febrero_2024[INGRESO]) -> 0 | E32: =SUMIF(Marzo_2024[CATEGORÍA],$B32,Marzo_2024[INGRESO]) -> 0 | F32: =SUMIF(Abril_2024[CATEGORÍA],$B32,Abril_2024[INGRESO]) -> 0 | G32: =SUMIF(Mayo_2024[CATEGORÍA],$B32,Mayo_2024[INGRESO]) -> 0 | H32: =SUMIF(Junio_2024[CATEGORÍA],$B32,Junio_2024[INGRESO]) -> 0 | I32: =SUMIF(Julio_2024[CATEGORÍA],$B32,Julio_2024[INGRESO]) -> 0 | J32: =SUMIF(Agosto_2024[CATEGORÍA],$B32,Agosto_2024[INGRESO]) -> 0 | K32: =SUMIF(Septiembre_2024[CATEGORÍA],$B32,Septiembre_2024[INGRESO]) -> 0 | L32: =SUMIF(Octubre_2024[CATEGORÍA],$B32,Octubre_2024[INGRESO]) -> 0 | M32: =SUMIF(Noviembre_2024[CATEGORÍA],$B32,Noviembre_2024[INGRESO]) -> 0 | N32: =SUMIF(Diciembre_2024[CATEGORÍA],$B32,Diciembre_2024[INGRESO]) -> 0 | O32: =SUM(D32:N32) -> 0
B34: TOTAL | C34: =SUM(C28:C32) -> 2600 | D34: =SUM(D28:D32) -> 5800 | E34: =SUM(E28:E32) -> 10200 | F34: =SUM(F28:F32) -> 13400 | G34: =SUM(G28:G32) -> 16600 | H34: =SUM(H28:H32) -> 19600 | I34: =SUM(I28:I32) -> 22800 | J34: =SUM(J28:J32) -> 31600 | ... O34: =SUM(O28:O32) -> 389810
B36: GASTOS OPERATIVOS
B37: RECURSOS HUMANOS
B38: Sueldos y Salarios | C38: =SUMIF(Enero_2024[CATEGORÍA],$B38,Enero_2024[EGRESO]) -> 24465.713 | D38: =SUMIF(Febrero_2024[CATEGORÍA],$B38,Febrero_2024[EGRESO]) -> 23700 | E38: =SUMIF(Marzo_2024[CATEGORÍA],$B38,Marzo_2024[EGRESO]) -> 34950 | F38: =SUMIF(Abril_2024[CATEGORÍA],$B38,Abril_2024[EGRESO]) -> 22900 | G38: =SUMIF(Mayo_2024[CATEGORÍA],$B38,Mayo_2024[EGRESO]) -> 22100 | H38: =SUMIF(Junio_2024[CATEGORÍA],$B38,Junio_2024[EGRESO]) -> 22100 | I38: =SUMIF(Julio_2024[CATEGORÍA],$B38,Julio_2024[EGRESO]) -> 25100 | J38: =SUMIF(Agosto_2024[CATEGORÍA],$B38,Agosto_2024[EGRESO]) -> 38550 | K38: =SUMIF(Septiembre_2024[CATEGORÍA],$B38,Septiembre_2024[EGRESO]) -> 32100 | L38: =SUMIF(Octubre_2024[CATEGORÍA],$B38,Octubre_2024[EGRESO]) -> 0 | M38: =SUMIF(Noviembre_2024[CATEGORÍA],$B38,Noviembre_2024[EGRESO]) -> 0 | N38: =SUMIF(Diciembre_2024[CATEGORÍA],$B38,Diciembre_2024[EGRESO]) -> 0 | O38: =SUM(D38:N38) -> 221500
B39: Aguinaldo | C39: =SUMIF(Enero_2024[CATEGORÍA],$B39,Enero_2024[EGRESO]) -> 0 | D39: =SUMIF(Febrero_2024[CATEGORÍA],$B39,Febrero_2024[EGRESO]) -> 0 | E39: =SUMIF(Marzo_2024[CATEGORÍA],$B39,Marzo_2024[EGRESO]) -> 0 | F39: =SUMIF(Abril_2024[CATEGORÍA],$B39,Abril_2024[EGRESO]) -> 0 | G39: =SUMIF(Mayo_2024[CATEGORÍA],$B39,Mayo_2024[EGRESO]) -> 0 | H39: =SUMIF(Junio_2024[CATEGORÍA],$B39,Junio_2024[EGRESO]) -> 0 | I39: =SUMIF(Julio_2024[CATEGORÍA],$B39,Julio_2024[EGRESO]) -> 0 | J39: =SUMIF(Agosto_2024[CATEGORÍA],$B39,Agosto_2024[EGRESO]) -> 0 | K39: =SUMIF(Septiembre_2024[CATEGORÍA],$B39,Septiembre_2024[EGRESO]) -> 0 | L39: =SUMIF(Octubre_2024[CATEGORÍA],$B39,Octubre_2024[EGRESO]) -> 0 | M39: =SUMIF(Noviembre_2024[CATEGORÍA],$B39,Noviembre_2024[EGRESO]) -> 0 | N39: =SUMIF(Diciembre_2024[CATEGORÍA],$B39,Diciembre_2024[EGRESO]) -> 0 | O39: =SUM(D39:N39) -> 0
B40: Prestamos de Nomina | C40: =SUMIF(Enero_2024[CATEGORÍA],$B40,Enero_2024[EGRESO]) -> 0 | D40: =SUMIF(Febrero_2024[CATEGORÍA],$B40,Febrero_2024[EGRESO]) -> 0 | E40: =SUMIF(Marzo_2024[CATEGORÍA],$B40,Marzo_2024[EGRESO]) -> 0 | F40: =SUMIF(Abril_2024[CATEGORÍA],$B40,Abril_2024[EGRESO]) -> 0 | G40: =SUMIF(Mayo_2024[CATEGORÍA],$B40,Mayo_2024[EGRESO]) -> 0 | H40: =SUMIF(Junio_2024[CATEGORÍA],$B40,Junio_2024[EGRESO]) -> 0 | I40: =SUMIF(Julio_2024[CATEGORÍA],$B40,Julio_2024[EGRESO]) -> 0 | J40: =SUMIF(Agosto_2024[CATEGORÍA],$B40,Agosto_2024[EGRESO]) -> 0 | K40: =SUMIF(Septiembre_2024[CATEGORÍA],$B40,Septiembre_2024[EGRESO]) -> 0 | L40: =SUMIF(Octubre_2024[CATEGORÍA],$B40,Octubre_2024[EGRESO]) -> 0 | M40: =SUMIF(Noviembre_2024[CATEGORÍA],$B40,Noviembre_2024[EGRESO]) -> 0 | N40: =SUMIF(Diciembre_2024[CATEGORÍA],$B40,Diciembre_2024[EGRESO]) -> 0 | O40: =SUM(D40:N40) -> 0
B41: Caja de Ahorro | C41: =SUMIF(Enero_2024[CATEGORÍA],$B41,Enero_2024[EGRESO]) -> 2600 | D41: =SUMIF(Febrero_2024[CATEGORÍA],$B41,Febrero_2024[EGRESO]) -> 3200 | E41: =SUMIF(Marzo_2024[CATEGORÍA],$B41,Marzo_2024[EGRESO]) -> 4400 | F41: =SUMIF(Abril_2024[CATEGORÍA],$B41,Abril_2024[EGRESO]) -> 3200 | G41: =SUMIF(Mayo_2024[CATEGORÍA],$B41,Mayo_2024[EGRESO]) -> 3200 | H41: =SUMIF(Junio_2024[CATEGORÍA],$B41,Junio_2024[EGRESO]) -> 3000 | I41: =SUMIF(Julio_2024[CATEGORÍA],$B41,Julio_2024[EGRESO]) -> 3200 | J41: =SUMIF(Agosto_2024[CATEGORÍA],$B41,Agosto_2024[EGRESO]) -> 4800 | K41: =SUMIF(Septiembre_2024[CATEGORÍA],$B41,Septiembre_2024[EGRESO]) -> 3200 | L41: =SUMIF(Octubre_2024[CATEGORÍA],$B41,Octubre_2024[EGRESO]) -> 0 | M41: =SUMIF(Noviembre_2024[CATEGORÍA],$B41,Noviembre_2024[EGRESO]) -> 0 | N41: =SUMIF(Diciembre_2024[CATEGORÍA],$B41,Diciembre_2024[EGRESO]) -> 0 | O41: =SUM(D41:N41) -> 28200
B42: Seguro Social | C42: =SUMIF(Enero_2024[CATEGORÍA],$B42,Enero_2024[EGRESO]) -> 0 | D42: =SUMIF(Febrero_2024[CATEGORÍA],$B42,Febrero_2024[EGRESO]) -> 0 | E42: =SUMIF(Marzo_2024[CATEGORÍA],$B42,Marzo_2024[EGRESO]) -> 0 | F42: =SUMIF(Abril_2024[CATEGORÍA],$B42,Abril_2024[EGRESO]) -> 0 | G42: =SUMIF(Mayo_2024[CATEGORÍA],$B42,Mayo_2024[EGRESO]) -> 0 | H42: =SUMIF(Junio_2024[CATEGORÍA],$B42,Junio_2024[EGRESO]) -> 0 | I42: =SUMIF(Julio_2024[CATEGORÍA],$B42,Julio_2024[EGRESO]) -> 0 | J42: =SUMIF(Agosto_2024[CATEGORÍA],$B42,Agosto_2024[EGRESO]) -> 0 | K42: =SUMIF(Septiembre_2024[CATEGORÍA],$B42,Septiembre_2024[EGRESO]) -> 0 | L42: =SUMIF(Octubre_2024[CATEGORÍA],$B42,Octubre_2024[EGRESO]) -> 0 | M42: =SUMIF(Noviembre_2024[CATEGORÍA],$B42,Noviembre_2024[EGRESO]) -> 0 | N42: =SUMIF(Diciembre_2024[CATEGORÍA],$B42,Diciembre_2024[EGRESO]) -> 0 | O42: =SUM(D42:N42) -> 0
B43: Gastos Medicos | C43: =SUMIF(Enero_2024[CATEGORÍA],$B43,Enero_2024[EGRESO]) -> 0 | D43: =SUMIF(Febrero_2024[CATEGORÍA],$B43,Febrero_2024[EGRESO]) -> 0 | E43: =SUMIF(Marzo_2024[CATEGORÍA],$B43,Marzo_2024[EGRESO]) -> 0 | F43: =SUMIF(Abril_2024[CATEGORÍA],$B43,Abril_2024[EGRESO]) -> 0 | G43: =SUMIF(Mayo_2024[CATEGORÍA],$B43,Mayo_2024[EGRESO]) -> 0 | H43: =SUMIF(Junio_2024[CATEGORÍA],$B43,Junio_2024[EGRESO]) -> 0 | I43: =SUMIF(Julio_2024[CATEGORÍA],$B43,Julio_2024[EGRESO]) -> 0 | J43: =SUMIF(Agosto_2024[CATEGORÍA],$B43,Agosto_2024[EGRESO]) -> 0 | K43: =SUMIF(Septiembre_2024[CATEGORÍA],$B43,Septiembre_2024[EGRESO]) -> 0 | L43: =SUMIF(Octubre_2024[CATEGORÍA],$B43,Octubre_2024[EGRESO]) -> 68 | M43: =SUMIF(Noviembre_2024[CATEGORÍA],$B43,Noviembre_2024[EGRESO]) -> 0 | N43: =SUMIF(Diciembre_2024[CATEGORÍA],$B43,Diciembre_2024[EGRESO]) -> 0 | O43: =SUM(D43:N43) -> 68
B44: ISR | C44: =SUMIF(Enero_2024[CATEGORÍA],$B44,Enero_2024[EGRESO]) -> 0 | D44: =SUMIF(Febrero_2024[CATEGORÍA],$B44,Febrero_2024[EGRESO]) -> 0 | E44: =SUMIF(Marzo_2024[CATEGORÍA],$B44,Marzo_2024[EGRESO]) -> 0 | F44: =SUMIF(Abril_2024[CATEGORÍA],$B44,Abril_2024[EGRESO]) -> 0 | G44: =SUMIF(Mayo_2024[CATEGORÍA],$B44,Mayo_2024[EGRESO]) -> 0 | H44: =SUMIF(Junio_2024[CATEGORÍA],$B44,Junio_2024[EGRESO]) -> 0 | I44: =SUMIF(Julio_2024[CATEGORÍA],$B44,Julio_2024[EGRESO]) -> 0 | J44: =SUMIF(Agosto_2024[CATEGORÍA],$B44,Agosto_2024[EGRESO]) -> 0 | K44: =SUMIF(Septiembre_2024[CATEGORÍA],$B44,Septiembre_2024[EGRESO]) -> 0 | L44: =SUMIF(Octubre_2024[CATEGORÍA],$B44,Octubre_2024[EGRESO]) -> 0 | M44: =SUMIF(Noviembre_2024[CATEGORÍA],$B44,Noviembre_2024[EGRESO]) -> 0 | N44: =SUMIF(Diciembre_2024[CATEGORÍA],$B44,Diciembre_2024[EGRESO]) -> 0 | O44: =SUM(D44:N44) -> 0
B45: INFONAVIT | C45: =SUMIF(Enero_2024[CATEGORÍA],$B45,Enero_2024[EGRESO]) -> 0 | D45: =SUMIF(Febrero_2024[CATEGORÍA],$B45,Febrero_2024[EGRESO]) -> 0 | E45: =SUMIF(Marzo_2024[CATEGORÍA],$B45,Marzo_2024[EGRESO]) -> 0 | F45: =SUMIF(Abril_2024[CATEGORÍA],$B45,Abril_2024[EGRESO]) -> 0 | G45: =SUMIF(Mayo_2024[CATEGORÍA],$B45,Mayo_2024[EGRESO]) -> 0 | H45: =SUMIF(Junio_2024[CATEGORÍA],$B45,Junio_2024[EGRESO]) -> 0 | I45: =SUMIF(Julio_2024[CATEGORÍA],$B45,Julio_2024[EGRESO]) -> 0 | J45: =SUMIF(Agosto_2024[CATEGORÍA],$B45,Agosto_2024[EGRESO]) -> 0 | K45: =SUMIF(Septiembre_2024[CATEGORÍA],$B45,Septiembre_2024[EGRESO]) -> 0 | L45: =SUMIF(Octubre_2024[CATEGORÍA],$B45,Octubre_2024[EGRESO]) -> 0 | M45: =SUMIF(Noviembre_2024[CATEGORÍA],$B45,Noviembre_2024[EGRESO]) -> 0 | N45: =SUMIF(Diciembre_2024[CATEGORÍA],$B45,Diciembre_2024[EGRESO]) -> 0 | O45: =SUM(D45:N45) -> 0
B46: 2.5% Sobre Nomina | C46: =SUMIF(Enero_2024[CATEGORÍA],$B46,Enero_2024[EGRESO]) -> 0 | D46: =SUMIF(Febrero_2024[CATEGORÍA],$B46,Febrero_2024[EGRESO]) -> 0 | E46: =SUMIF(Marzo_2024[CATEGORÍA],$B46,Marzo_2024[EGRESO]) -> 0 | F46: =SUMIF(Abril_2024[CATEGORÍA],$B46,Abril_2024[EGRESO]) -> 0 | G46: =SUMIF(Mayo_2024[CATEGORÍA],$B46,Mayo_2024[EGRESO]) -> 0 | H46: =SUMIF(Junio_2024[CATEGORÍA],$B46,Junio_2024[EGRESO]) -> 0 | I46: =SUMIF(Julio_2024[CATEGORÍA],$B46,Julio_2024[EGRESO]) -> 0 | J46: =SUMIF(Agosto_2024[CATEGORÍA],$B46,Agosto_2024[EGRESO]) -> 0 | K46: =SUMIF(Septiembre_2024[CATEGORÍA],$B46,Septiembre_2024[EGRESO]) -> 0 | L46: =SUMIF(Octubre_2024[CATEGORÍA],$B46,Octubre_2024[EGRESO]) -> 0 | M46: =SUMIF(Noviembre_2024[CATEGORÍA],$B46,Noviembre_2024[EGRESO]) -> 0 | N46: =SUMIF(Diciembre_2024[CATEGORÍA],$B46,Diciembre_2024[EGRESO]) -> 0 | O46: =SUM(D46:N46) -> 0
B47: Vacaciones NO Disfrutadas | C47: =SUMIF(Enero_2024[CATEGORÍA],$B47,Enero_2024[EGRESO]) -> 0 | D47: =SUMIF(Febrero_2024[CATEGORÍA],$B47,Febrero_2024[EGRESO]) -> 0 | E47: =SUMIF(Marzo_2024[CATEGORÍA],$B47,Marzo_2024[EGRESO]) -> 0 | F47: =SUMIF(Abril_2024[CATEGORÍA],$B47,Abril_2024[EGRESO]) -> 0 | G47: =SUMIF(Mayo_2024[CATEGORÍA],$B47,Mayo_2024[EGRESO]) -> 0 | H47: =SUMIF(Junio_2024[CATEGORÍA],$B47,Junio_2024[EGRESO]) -> 0 | I47: =SUMIF(Julio_2024[CATEGORÍA],$B47,Julio_2024[EGRESO]) -> 0 | J47: =SUMIF(Agosto_2024[CATEGORÍA],$B47,Agosto_2024[EGRESO]) -> 0 | K47: =SUMIF(Septiembre_2024[CATEGORÍA],$B47,Septiembre_2024[EGRESO]) -> 0 | L47: =SUMIF(Octubre_2024[CATEGORÍA],$B47,Octubre_2024[EGRESO]) -> 0 | M47: =SUMIF(Noviembre_2024[CATEGORÍA],$B47,Noviembre_2024[EGRESO]) -> 0 | N47: =SUMIF(Diciembre_2024[CATEGORÍA],$B47,Diciembre_2024[EGRESO]) -> 0 | O47: =SUM(D47:N47) -> 0
...

Sheet Cuentas
B2: CUENTAS CORRIENTES | F2: =SUM(F3:F4) -> 0
B3: Cheques BBVA | F3: 0
B4: Efectivo | F4: 0
B5: JC Jr.
B6: LINEAS DE CREDITO | F6: =SUM(F7:F8) -> 0
F7: 0
F8: 0
B10: OTROS ACTIVOS | F10: =SUM(F11:F12) -> 0
F11: 0
F12: 0
B14: OTROS PASIVOS | F14: =SUM(F15:F16) -> 0
F15: 0
F16: 0

Sheet Entradas y Salidas
A2: HISTORIAL DE TRANSACCIONES
B4: ENERO 2025
B5: CUENTA | C5: FECHA | D5: INGRESO | E5: EGRESO | F5: BENEFICIARIO/PROVEEDOR | G5: NO. FACTURA | H5: NO. PROYECTO | I5: DESCRIPCION | J5: CATEGORÍA | K5: SUB CATEGORIA | L5: EQUILIBRAR
B6: Cheques BBVA | C6: 45293 | E6: 1492.81 | F6: VAQUEIROS FERRETEROS | G6: PENDIENTE | H6: GASTOS INTERNOS | I6: Contectores de Mangueras | J6: Articulos Infraestructura Interna | L6: =IF(ISERROR(OFFSET(L6,-1,0,1,1)+D6-E6),D6-E6,OFFSET(L6,-1,0,1,1)+D6-E6) -> -1492.81
B7: Efectivo | C7: 45295 | E7: 356.66667 | F7: MANANTIAL DE VIDA | G7: NO APLICA | H7: GASTOS INTERNOS | I7: Pastel y Rosca | J7: Otro RRHH | L7: =IF(ISERROR(OFFSET(L7,-1,0,1,1)+D7-E7),D7-E7,OFFSET(L7,-1,0,1,1)+D7-E7) -> -1849.4767
B8: Efectivo | C8: 45661 | E8: 4137.1429 | F8: JOSE ACOSTA FARIAS | G8: NO APLICA | H8: NOMINA | J8: Sueldos y Salarios | L8: =IF(ISERROR(OFFSET(L8,-1,0,1,1)+'[1]Entradas y Salidas'!D9-'[1]Entradas y Salidas'!E9),'[1]Entradas y Salidas'!D9-'[1]Entradas y Salidas'!E9,OFFSET(L8,-1,0,1,1)+'[1]Entradas y Salidas'!D9-'[1]Entradas y Salidas'!E9) -> -2349.4767
B9: Efectivo | C9: 45661 | E9: 3420 | F9: DERIK ALEXIS CHABLE PASCUAL | G9: NO APLICA | H9: NOMINA | J9: Sueldos y Salarios | L9: =IF(ISERROR(OFFSET(L9,-1,0,1,1)+D9-E9),D9-E9,OFFSET(L9,-1,0,1,1)+D9-E9) -> -5769.4767
B10: Efectivo | C10: 45661 | E10: 200 | F10: DERIK ALEXIS CHABLE PASCUAL | G10: NO APLICA | H10: CAJA DE AHORRO | J10: Caja de Ahorro | L10: =IF(ISERROR(OFFSET(L10,-1,0,1,1)+D10-E10),D10-E10,OFFSET(L10,-1,0,1,1)+D10-E10) -> -5969.4767
B11: Efectivo | C11: 45661 | E11: 1968.57 | F11: YARA ODILIA RIVERA MARQUEZ | G11: NO APLICA | H11: NOMINA | J11: Sueldos y Salarios | L11: =IF(ISERROR(OFFSET(L11,-1,0,1,1)+D11-E11),D11-E11,OFFSET(L11,-1,0,1,1)+D11-E11) -> -7938.0467
B12: Efectivo | C12: 45661 | E12: 200 | F12: YARA ODILIA RIVERA MARQUEZ | G12: NO APLICA | H12: CAJA DE AHORRO | J12: Caja de Ahorro | L12: =IF(ISERROR(OFFSET(L12,-1,0,1,1)+D12-E12),D12-E12,OFFSET(L12,-1,0,1,1)+D12-E12) -> -8138.0467
B13: Efectivo | C13: 45661 | E13: 900 | F13: SELENE RIVERA ALCAZAR | G13: NO APLICA | H13: NOMINA | J13: Sueldos y Salarios | L13: =IF(ISERROR(OFFSET(L13,-1,0,1,1)+D13-E13),D13-E13,OFFSET(L13,-1,0,1,1)+D13-E13) -> -9038.0467
B14: Efectivo | C14: 45661 | E14: 200 | F14: SELENE RIVERA ALCAZAR | G14: NO APLICA | H14: CAJA DE AHORRO | J14: Caja de Ahorro | L14: =IF(ISERROR(OFFSET(L14,-1,0,1,1)+D14-E14),D14-E14,OFFSET(L14,-1,0,1,1)+D14-E14) -> -9238.0467
B15: Efectivo | C15: 45661 | E15: 2400 | F15: PATRICIO ACOSTA FARIAS | G15: NO APLICA | H15: NOMINA | J15: Sueldos y Salarios | L15: =IF(ISERROR(OFFSET(L15,-1,0,1,1)+D15-E15),D15-E15,OFFSET(L15,-1,0,1,1)+D15-E15) -> -11638.047
B16: Efectivo | C16: 45661 | E16: 400 | F16: PATRICIO ACOSTA FARIAS | G16: NO APLICA | H16: CAJA DE AHORRO | J16: Caja de Ahorro | L16: =IF(ISERROR(OFFSET(L16,-1,0,1,1)+D16-E16),D16-E16,OFFSET(L16,-1,0,1,1)+D16-E16) -> -12038.047
B17: Efectivo | C17: 45666 | E17: 2639 | F17: JYY AGROPECUARIA DE TABASCO | G17: BA 10871 | H17: GASTOS INTERNOS | I17: Alimento Hormonado y Dyno | J17: Compra de Alimento | L17: =IF(ISERROR(OFFSET(L17,-1,0,1,1)+D17-E17),D17-E17,OFFSET(L17,-1,0,1,1)+D17-E17) -> -14677.047
B18: Efectivo | C18: 45666 | E18: 600 | F18: FERRETERIA CHISPITA | G18: NO APLICA | H18: GASTOS INTERNOS | I18: Malla Mirinaque | J18: Articulos Infraestructura Interna | L18: =IF(ISERROR(OFFSET(L18,-1,0,1,1)+D18-E18),D18-E18,OFFSET(L18,-1,0,1,1)+D18-E18) -> -15277.047
B19: Efectivo | C19: 45667 | E19: 682.19 | F19: VAQUEIROS FERRETEROS | G19: C 601757 | H19: GASTOS INTERNOS | I19: Tensores, Conectores PVC Macho/Hembra | J19: Articulos Infraestructura Interna | L19: =IF(ISERROR(OFFSET(L19,-1,0,1,1)+D19-E19),D19-E19,OFFSET(L19,-1,0,1,1)+D19-E19) -> -15959.237
B20: Efectivo | C20: 45670 | D20: 1200 | F20: JORGE GAXIOLA | G20: NO APLICA | H20: GAM-0125001 | I20: Venta Alevines (1,000) | J20: Venta de Alevines | L20: =IF(ISERROR(OFFSET(L20,-1,0,1,1)+D20-E20),D20-E20,OFFSET(L20,-1,0,1,1)+D20-E20) -> -14759.237
B21: Cheques BBVA | C21: 45670 | D21: 8100 | F21: ELEAZER RIOS JIMENEZ / ACUICOLA TRES RIOS | G21: NO APLICA | H21: GAM-0125002 | I21: Venta Alevines (6,750) | J21: Venta de Alevines | L21: =IF(ISERROR(OFFSET(L21,-1,0,1,1)+D21-E21),D21-E21,OFFSET(L21,-1,0,1,1)+D21-E21) -> -6659.2367
B22: Efectivo | C22: 45671 | E22: 462 | F22: MATERIALES "SAN ROMAN" | G22: A4-7770 | H22: GASTOS INTERNOS | I22: Cemento Gris y Cal | J22: Material de Construccion Interno | L22: =IF(ISERROR(OFFSET(L22,-1,0,1,1)+D22-E22),D22-E22,OFFSET(L22,-1,0,1,1)+D22-E22) -> -7121.2367
B23: Efectivo | C23: 45675 | E23: 4480 | F23: JOSE ACOSTA FARIAS | G23: NO APLICA | H23: NOMINA | J23: Sueldos y Salarios | L23: =IF(ISERROR(OFFSET(L23,-1,0,1,1)+D23-E23),D23-E23,OFFSET(L23,-1,0,1,1)+D23-E23) -> -11601.237
B24: Efectivo | C24: 45675 | E24: 3520 | F24: DERIK ALEXIS CHABLE PASCUAL | G24: NO APLICA | H24: NOMINA | J24: Sueldos y Salarios | L24: =IF(ISERROR(OFFSET(L24,-1,0,1,1)+D24-E24),D24-E24,OFFSET(L24,-1,0,1,1)+D24-E24) -> -15121.237
B25: Efectivo | C25: 45675 | E25: 400 | F25: DERIK ALEXIS CHABLE PASCUAL | G25: NO APLICA | H25: CAJA DE AHORRO | J25: Caja de Ahorro | L25: =IF(ISERROR(OFFSET(L25,-1,0,1,1)+D25-E25),D25-E25,OFFSET(L25,-1,0,1,1)+D25-E25) -> -15521.237
B26: Efectivo | C26: 45675 | E26: 2040 | F26: YARA ODILIA RIVERA MARQUEZ | G26: NO APLICA | H26: NOMINA | J26: Sueldos y Salarios | L26: =IF(ISERROR(OFFSET(L26,-1,0,1,1)+D26-E26),D26-E26,OFFSET(L26,-1,0,1,1)+D26-E26) -> -17561.237
B27: Efectivo | C27: 45675 | E27: 400 | F27: YARA ODILIA RIVERA MARQUEZ | G27: NO APLICA | H27: CAJA DE AHORRO | J27: Caja de Ahorro | L27: =IF(ISERROR(OFFSET(L27,-1,0,1,1)+D27-E27),D27-E27,OFFSET(L27,-1,0,1,1)+D27-E27) -> -17961.237
B28: Efectivo | C28: 45675 | E28: 800 | F28: SELENE RIVERA ALCAZAR | G28: NO APLICA | H28: NOMINA | J28: Sueldos y Salarios | L28: =IF(ISERROR(OFFSET(L28,-1,0,1,1)+D28-E28),D28-E28,OFFSET(L28,-1,0,1,1)+D28-E28) -> -18761.237
B29: Efectivo | C29: 45675 | E29: 400 | F29: SELENE RIVERA ALCAZAR | G29: NO APLICA | H29: CAJA DE AHORRO | J29: Caja de Ahorro | L29: =IF(ISERROR(OFFSET(L29,-1,0,1,1)+D29-E29),D29-E29,OFFSET(L29,-1,0,1,1)+D29-E29) -> -19161.237
B30: Efectivo | C30: 45675 | E30: 800 | F30: PATRICIO ACOSTA FARIAS | G30: NO APLICA | H30: NOMINA | J30: Sueldos y Salarios | L30: =IF(ISERROR(OFFSET(L30,-1,0,1,1)+D30-E30),D30-E30,OFFSET(L30,-1,0,1,1)+D30-E30) -> -19961.237
B31: Efectivo | C31: 45675 | E31: 400 | F31: PATRICIO ACOSTA FARIAS | G31: NO APLICA | H31: CAJA DE AHORRO | J31: Caja de Ahorro | L31: =IF(ISERROR(OFFSET(L31,-1,0,1,1)+D31-E31),D31-E31,OFFSET(L31,-1,0,1,1)+D31-E31) -> -20361.237
B32: Efectivo | C32: 45675 | D32: 504 | F32: ALEJANDRO DOMINGUEZ | G32: NO APLICA | H32: GAM-0125003 | I32: Venta Alevines (420) | J32: Venta de Alevines | L32: =IF(ISERROR(OFFSET(L32,-1,0,1,1)+D32-E32),D32-E32,OFFSET(L32,-1,0,1,1)+D32-E32) -> -19857.237
B33: Cheques BBVA | C33: 45677 | E33: 937.5 | F33: POLIETILENOS DE TABASCO | G33: PENDIENTE | H33: GASTOS INTERNOS | I33: Bolsas 60 x 90 | J33: Articulos Infraestructura Interna | L33: =IF(ISERROR(OFFSET(L33,-1,0,1,1)+D33-E33),D33-E33,OFFSET(L33,-1,0,1,1)+D33-E33) -> -20794.737
B34: Efectivo | C34: 45677 | D34: 6840 | F34: ARTURO RABELO | G34: NO APLICA | H34: GAM-0125004 | I34: Venta Alevines (7,500) | J34: Venta de Alevines | L34: =IF(ISERROR(OFFSET(L34,-1,0,1,1)+D34-E34),D34-E34,OFFSET(L34,-1,0,1,1)+D34-E34) -> -13954.737
B35: Efectivo | C35: 45680 | D35: 2400 | F35: ALEJANDRO DOMINGUEZ | G35: NO APLICA | H35: GAM-0125005 | I35: Venta Alevines (2,000) | J35: Venta de Alevines | L35: =IF(ISERROR(OFFSET(L35,-1,0,1,1)+D35-E35),D35-E35,OFFSET(L35,-1,0,1,1)+D35-E35) -> -11554.737
B36: Efectivo | C36: 45682 | E36: 180 | F36: MATERIALES DE CONSTRUCCION ALAMILLA | G36: PENDIENTE | H36: GASTOS INTERNOS | I36: Conectores PVC | J36: Articulos Infraestructura Interna | L36: =IF(ISERROR(OFFSET(L36,-1,0,1,1)+D36-E36),D36-E36,OFFSET(L36,-1,0,1,1)+D36-E36) -> -11734.737
B37: Efectivo | C37: 45684 | D37: 3000 | F37: JAIME LASTRA | G37: NO APLICA | H37: GAM-0125006 | I37: Venta Alevines (2,500) | J37: Venta de Alevines | L37: =IF(ISERROR(OFFSET(L37,-1,0,1,1)+D37-E37),D37-E37,OFFSET(L37,-1,0,1,1)+D37-E37) -> -8734.7367
L38: =IF(ISERROR(OFFSET(L38,-1,0,1,1)+D38-E38),D38-E38,OFFSET(L38,-1,0,1,1)+D38-E38) -> -8734.7367
L39: =IF(ISERROR(OFFSET(L39,-1,0,1,1)+D39-E39),D39-E39,OFFSET(L39,-1,0,1,1)+D39-E39) -> -8734.7367
L40: =IF(ISERROR(OFFSET(L40,-1,0,1,1)+D40-E40),D40-E40,OFFSET(L40,-1,0,1,1)+D40-E40) -> -8734.7367
L41: =IF(ISERROR(OFFSET(L41,-1,0,1,1)+D41-E41),D41-E41,OFFSET(L41,-1,0,1,1)+D41-E41) -> -8734.7367
L42: =IF(ISERROR(OFFSET(L42,-1,0,1,1)+D42-E42),D42-E42,OFFSET(L42,-1,0,1,1)+D42-E42) -> -8734.7367
...

Sheet Estimado
B1: SEGUIMIENTO DE TESORERIA
C2: ENERO | D2: FEBRERO | E2: MARZO | F2: ABRIL | G2: MAYO | H2: JUNIO | I2: JULIO | J2: AGOSTO | K2: SEPTIEMBRE | L2: OCTUBRE | M2: NOVIEMBRE | N2: DICIEMBRE
B3: Saldo inicial [Saldo en cuenta] | C3: 0 | D3: =C7 -> 0 | E3: =D7 -> 0 | F3: =E7 -> 0 | G3: =F7 -> 0 | H3: =G7 -> 0 | I3: =H7 -> 0 | J3: =I7 -> 0 | K3: =J7 -> 0 | ... N3: =M7 -> 0
B4: Ingresos Estimados | C4: =C22 -> 0 | D4: =D22 -> 0 | E4: =E22 -> 0 | F4: =F22 -> 0 | G4: =G22 -> 0 | H4: =H22 -> 0 | I4: =I22 -> 0 | J4: =J22 -> 0 | ... N4: =N22 -> 0
B5: Egresos Estimados | C5: =C74 -> 0 | D5: =D74 -> 0 | E5: =E74 -> 0 | F5: =F74 -> 0 | G5: =G74 -> 0 | H5: =H74 -> 0 | I5: =I74 -> 0 | J5: =J74 -> 0 | ... N5: =N74 -> 0
B6: INGRESOS NETOS | C6: =C4-C5 -> 0 | D6: =D4-D5 -> 0 | E6: =E4-E5 -> 0 | F6: =F4-F5 -> 0 | G6: =G4-G5 -> 0 | H6: =H4-H5 -> 0 | I6: =I4-I5 -> 0 | J6: =J4-J5 -> 0 | ... N6: =N4-N5 -> 0
B7: Saldo final proyectado | C7: =C4-C5+C3 -> 0 | D7: =D4-D5+D3 -> 0 | E7: =E4-E5+E3 -> 0 | F7: =F4-F5+F3 -> 0 | G7: =G4-G5+G3 -> 0 | H7: =H4-H5+H3 -> 0 | I7: =I4-I5+I3 -> 0 | J7: =J4-J5+J3 -> 0 | ... N7: =N4-N5+N3 -> 0
B9: INGRESOS
B11: Venta de Alevines | C11: =SUMIF(EneEst2024[CATEGORÍA],$B11,EneEst2024[INGRESO]) -> 0 | D11: =SUMIF(FebEst2024[CATEGORÍA],$B11,FebEst2024[INGRESO]) -> 0 | E11: =SUMIF(MarEst2024[CATEGORÍA],$B11,MarEst2024[INGRESO]) -> 0 | F11: =SUMIF(AbrEst2024[CATEGORÍA],$B11,AbrEst2024[INGRESO]) -> 0 | G11: =SUMIF(MayEst_2024[CATEGORÍA],$B11,MayEst_2024[INGRESO]) -> 0 | H11: =SUMIF(JunEst_2024[CATEGORÍA],$B11,JunEst_2024[INGRESO]) -> 0 | I11: =SUMIF(JulEst_2024[CATEGORÍA],$B11,JulEst_2024[INGRESO]) -> 0 | J11: =SUMIF(AgoEst_2024[CATEGORÍA],$B11,AgoEst_2024[INGRESO]) -> 0 | K11: =SUMIF(SepEst_2024[CATEGORÍA],$B11,SepEst_2024[INGRESO]) -> 0 | L11: =SUMIF(OctEst_2024[CATEGORÍA],$B11,OctEst_2024[INGRESO]) -> 0 | M11: =SUMIF(NovEst_2024[CATEGORÍA],$B11,NovEst_2024[INGRESO]) -> 0 | N11: =SUMIF(DicEst_2024[CATEGORÍA],$B11,DicEst_2024[INGRESO]) -> 0 | O11: =SUM(D11:N11) -> 0
B12: Venta de Alimento | C12: =SUMIF(EneEst2024[CATEGORÍA],$B12,EneEst2024[INGRESO]) -> 0 | D12: =SUMIF(FebEst2024[CATEGORÍA],$B12,FebEst2024[INGRESO]) -> 0 | E12: =SUMIF(MarEst2024[CATEGORÍA],$B12,MarEst2024[INGRESO]) -> 0 | F12: =SUMIF(AbrEst2024[CATEGORÍA],$B12,AbrEst2024[INGRESO]) -> 0 | G12: =SUMIF(MayEst_2024[CATEGORÍA],$B12,MayEst_2024[INGRESO]) -> 0 | H12: =SUMIF(JunEst_2024[CATEGORÍA],$B12,JunEst_2024[INGRESO]) -> 0 | I12: =SUMIF(JulEst_2024[CATEGORÍA],$B12,JulEst_2024[INGRESO]) -> 0 | J12: =SUMIF(AgoEst_2024[CATEGORÍA],$B12,AgoEst_2024[INGRESO]) -> 0 | K12: =SUMIF(SepEst_2024[CATEGORÍA],$B12,SepEst_2024[INGRESO]) -> 0 | L12: =SUMIF(OctEst_2024[CATEGORÍA],$B12,OctEst_2024[INGRESO]) -> 0 | M12: =SUMIF(NovEst_2024[CATEGORÍA],$B12,NovEst_2024[INGRESO]) -> 0 | N12: =SUMIF(DicEst_2024[CATEGORÍA],$B12,DicEst_2024[INGRESO]) -> 0 | O12: =SUM(D12:N12) -> 0
B13: Venta Medicamentos/Vitaminas | C13: =SUMIF(EneEst2024[CATEGORÍA],$B13,EneEst2024[INGRESO]) -> 0 | D13: =SUMIF(FebEst2024[CATEGORÍA],$B13,FebEst2024[INGRESO]) -> 0 | E13: =SUMIF(MarEst2024[CATEGORÍA],$B13,MarEst2024[INGRESO]) -> 0 | F13: =SUMIF(AbrEst2024[CATEGORÍA],$B13,AbrEst2024[INGRESO]) -> 0 | G13: =SUMIF(MayEst_2024[CATEGORÍA],$B13,MayEst_2024[INGRESO]) -> 0 | H13: =SUMIF(JunEst_2024[CATEGORÍA],$B13,JunEst_2024[INGRESO]) -> 0 | I13: =SUMIF(JulEst_2024[CATEGORÍA],$B13,JulEst_2024[INGRESO]) -> 0 | J13: =SUMIF(AgoEst_2024[CATEGORÍA],$B13,AgoEst_2024[INGRESO]) -> 0 | K13: =SUMIF(SepEst_2024[CATEGORÍA],$B13,SepEst_2024[INGRESO]) -> 0 | L13: =SUMIF(OctEst_2024[CATEGORÍA],$B13,OctEst_2024[INGRESO]) -> 0 | M13: =SUMIF(NovEst_2024[CATEGORÍA],$B13,NovEst_2024[INGRESO]) -> 0 | N13: =SUMIF(DicEst_2024[CATEGORÍA],$B13,DicEst_2024[INGRESO]) -> 0 | O13: =SUM(D13:N13) -> 0
B14: Ingresos por intereses | C14: =SUMIF(EneEst2024[CATEGORÍA],$B14,EneEst2024[INGRESO]) -> 0 | D14: =SUMIF(FebEst2024[CATEGORÍA],$B14,FebEst2024[INGRESO]) -> 0 | E14: =SUMIF(MarEst2024[CATEGORÍA],$B14,MarEst2024[INGRESO]) -> 0 | F14: =SUMIF(AbrEst2024[CATEGORÍA],$B14,AbrEst2024[INGRESO]) -> 0 | G14: =SUMIF(MayEst_2024[CATEGORÍA],$B14,MayEst_2024[INGRESO]) -> 0 | H14: =SUMIF(JunEst_2024[CATEGORÍA],$B14,JunEst_2024[INGRESO]) -> 0 | I14: =SUMIF(JulEst_2024[CATEGORÍA],$B14,JulEst_2024[INGRESO]) -> 0 | J14: =SUMIF(AgoEst_2024[CATEGORÍA],$B14,AgoEst_2024[INGRESO]) -> 0 | K14: =SUMIF(SepEst_2024[CATEGORÍA],$B14,SepEst_2024[INGRESO]) -> 0 | L14: =SUMIF(OctEst_2024[CATEGORÍA],$B14,OctEst_2024[INGRESO]) -> 0 | M14: =SUMIF(NovEst_2024[CATEGORÍA],$B14,NovEst_2024[INGRESO]) -> 0 | N14: =SUMIF(DicEst_2024[CATEGORÍA],$B14,DicEst_2024[INGRESO]) -> 0 | O14: =SUM(D14:N14) -> 0
B15: Servicios de Gestion | C15: =SUMIF(EneEst2024[CATEGORÍA],$B15,EneEst2024[INGRESO]) -> 0 | D15: =SUMIF(FebEst2024[CATEGORÍA],$B15,FebEst2024[INGRESO]) -> 0 | E15: =SUMIF(MarEst2024[CATEGORÍA],$B15,MarEst2024[INGRESO]) -> 0 | F15: =SUMIF(AbrEst2024[CATEGORÍA],$B15,AbrEst2024[INGRESO]) -> 0 | G15: =SUMIF(MayEst_2024[CATEGORÍA],$B15,MayEst_2024[INGRESO]) -> 0 | H15: =SUMIF(JunEst_2024[CATEGORÍA],$B15,JunEst_2024[INGRESO]) -> 0 | I15: =SUMIF(JulEst_2024[CATEGORÍA],$B15,JulEst_2024[INGRESO]) -> 0 | J15: =SUMIF(AgoEst_2024[CATEGORÍA],$B15,AgoEst_2024[INGRESO]) -> 0 | K15: =SUMIF(SepEst_2024[CATEGORÍA],$B15,SepEst_2024[INGRESO]) -> 0 | L15: =SUMIF(OctEst_2024[CATEGORÍA],$B15,OctEst_2024[INGRESO]) -> 0 | M15: =SUMIF(NovEst_2024[CATEGORÍA],$B15,NovEst_2024[INGRESO]) -> 0 | N15: =SUMIF(DicEst_2024[CATEGORÍA],$B15,DicEst_2024[INGRESO]) -> 0 | O15: =SUM(D15:N15) -> 0
B16: GPS Over Track Cobro | C16: =SUMIF(EneEst2024[CATEGORÍA],$B16,EneEst2024[INGRESO]) -> 0 | D16: =SUMIF(FebEst2024[CATEGORÍA],$B16,FebEst2024[INGRESO]) -> 0 | E16: =SUMIF(MarEst2024[CATEGORÍA],$B16,MarEst2024[INGRESO]) -> 0 | F16: =SUMIF(AbrEst2024[CATEGORÍA],$B16,AbrEst2024[INGRESO]) -> 0 | G16: =SUMIF(MayEst_2024[CATEGORÍA],$B16,MayEst_2024[INGRESO]) -> 0 | H16: =SUMIF(JunEst_2024[CATEGORÍA],$B16,JunEst_2024[INGRESO]) -> 0 | I16: =SUMIF(JulEst_2024[CATEGORÍA],$B16,JulEst_2024[INGRESO]) -> 0 | J16: =SUMIF(AgoEst_2024[CATEGORÍA],$B16,AgoEst_2024[INGRESO]) -> 0 | K16: =SUMIF(SepEst_2024[CATEGORÍA],$B16,SepEst_2024[INGRESO]) -> 0 | L16: =SUMIF(OctEst_2024[CATEGORÍA],$B16,OctEst_2024[INGRESO]) -> 0 | M16: =SUMIF(NovEst_2024[CATEGORÍA],$B16,NovEst_2024[INGRESO]) -> 0 | N16: =SUMIF(DicEst_2024[CATEGORÍA],$B16,DicEst_2024[INGRESO]) -> 0 | O16: =SUM(D16:N16) -> 0
B17: Reembolsos | C17: =SUMIF(EneEst2024[CATEGORÍA],$B17,EneEst2024[INGRESO]) -> 0 | D17: =SUMIF(FebEst2024[CATEGORÍA],$B17,FebEst2024[INGRESO]) -> 0 | E17: =SUMIF(MarEst2024[CATEGORÍA],$B17,MarEst2024[INGRESO]) -> 0 | F17: =SUMIF(AbrEst2024[CATEGORÍA],$B17,AbrEst2024[INGRESO]) -> 0 | G17: =SUMIF(MayEst_2024[CATEGORÍA],$B17,MayEst_2024[INGRESO]) -> 0 | H17: =SUMIF(JunEst_2024[CATEGORÍA],$B17,JunEst_2024[INGRESO]) -> 0 | I17: =SUMIF(JulEst_2024[CATEGORÍA],$B17,JulEst_2024[INGRESO]) -> 0 | J17: =SUMIF(AgoEst_2024[CATEGORÍA],$B17,AgoEst_2024[INGRESO]) -> 0 | K17: =SUMIF(SepEst_2024[CATEGORÍA],$B17,SepEst_2024[INGRESO]) -> 0 | L17: =SUMIF(OctEst_2024[CATEGORÍA],$B17,OctEst_2024[INGRESO]) -> 0 | M17: =SUMIF(NovEst_2024[CATEGORÍA],$B17,NovEst_2024[INGRESO]) -> 0 | N17: =SUMIF(DicEst_2024[CATEGORÍA],$B17,DicEst_2024[INGRESO]) -> 0 | O17: =SUM(D17:N17) -> 0
B18: Comisiones | C18: =SUMIF(EneEst2024[CATEGORÍA],$B18,EneEst2024[INGRESO]) -> 0 | D18: =SUMIF(FebEst2024[CATEGORÍA],$B18,FebEst2024[INGRESO]) -> 0 | E18: =SUMIF(MarEst2024[CATEGORÍA],$B18,MarEst2024[INGRESO]) -> 0 | F18: =SUMIF(AbrEst2024[CATEGORÍA],$B18,AbrEst2024[INGRESO]) -> 0 | G18: =SUMIF(MayEst_2024[CATEGORÍA],$B18,MayEst_2024[INGRESO]) -> 0 | H18: =SUMIF(JunEst_2024[CATEGORÍA],$B18,JunEst_2024[INGRESO]) -> 0 | I18: =SUMIF(JulEst_2024[CATEGORÍA],$B18,JulEst_2024[INGRESO]) -> 0 | J18: =SUMIF(AgoEst_2024[CATEGORÍA],$B18,AgoEst_2024[INGRESO]) -> 0 | K18: =SUMIF(SepEst_2024[CATEGORÍA],$B18,SepEst_2024[INGRESO]) -> 0 | L18: =SUMIF(OctEst_2024[CATEGORÍA],$B18,OctEst_2024[INGRESO]) -> 0 | M18: =SUMIF(NovEst_2024[CATEGORÍA],$B18,NovEst_2024[INGRESO]) -> 0 | N18: =SUMIF(DicEst_2024[CATEGORÍA],$B18,DicEst_2024[INGRESO]) -> 0 | O18: =SUM(D18:N18) -> 0
B19: Fondeo Externo y Pasivos | C19: =SUMIF(EneEst2024[CATEGORÍA],$B19,EneEst2024[INGRESO]) -> 0 | D19: =SUMIF(FebEst2024[CATEGORÍA],$B19,FebEst2024[INGRESO]) -> 0 | E19: =SUMIF(MarEst2024[CATEGORÍA],$B19,MarEst2024[INGRESO]) -> 0 | F19: =SUMIF(AbrEst2024[CATEGORÍA],$B19,AbrEst2024[INGRESO]) -> 0 | G19: =SUMIF(MayEst_2024[CATEGORÍA],$B19,MayEst_2024[INGRESO]) -> 0 | H19: =SUMIF(JunEst_2024[CATEGORÍA],$B19,JunEst_2024[INGRESO]) -> 0 | I19: =SUMIF(JulEst_2024[CATEGORÍA],$B19,JulEst_2024[INGRESO]) -> 0 | J19: =SUMIF(AgoEst_2024[CATEGORÍA],$B19,AgoEst_2024[INGRESO]) -> 0 | K19: =SUMIF(SepEst_2024[CATEGORÍA],$B19,SepEst_2024[INGRESO]) -> 0 | L19: =SUMIF(OctEst_2024[CATEGORÍA],$B19,OctEst_2024[INGRESO]) -> 0 | M19: =SUMIF(NovEst_2024[CATEGORÍA],$B19,NovEst_2024[INGRESO]) -> 0 | N19: =SUMIF(DicEst_2024[CATEGORÍA],$B19,DicEst_2024[INGRESO]) -> 0 | O19: =SUM(D19:N19) -> 0
B20: Miscelaneo | C20: =SUMIF(EneEst2024[CATEGORÍA],$B20,EneEst2024[INGRESO]) -> 0 | D20: =SUMIF(FebEst2024[CATEGORÍA],$B20,FebEst2024[INGRESO]) -> 0 | E20: =SUMIF(MarEst2024[CATEGORÍA],$B20,MarEst2024[INGRESO]) -> 0 | F20: =SUMIF(AbrEst2024[CATEGORÍA],$B20,AbrEst2024[INGRESO]) -> 0 | G20: =SUMIF(MayEst_2024[CATEGORÍA],$B20,MayEst_2024[INGRESO]) -> 0 | H20: =SUMIF(JunEst_2024[CATEGORÍA],$B20,JunEst_2024[INGRESO]) -> 0 | I20: =SUMIF(JulEst_2024[CATEGORÍA],$B20,JulEst_2024[INGRESO]) -> 0 | J20: =SUMIF(AgoEst_2024[CATEGORÍA],$B20,AgoEst_2024[INGRESO]) -> 0 | K20: =SUMIF(SepEst_2024[CATEGORÍA],$B20,SepEst_2024[INGRESO]) -> 0 | L20: =SUMIF(OctEst_2024[CATEGORÍA],$B20,OctEst_2024[INGRESO]) -> 0 | M20: =SUMIF(NovEst_2024[CATEGORÍA],$B20,NovEst_2024[INGRESO]) -> 0 | N20: =SUMIF(DicEst_2024[CATEGORÍA],$B20,DicEst_2024[INGRESO]) -> 0 | O20: =SUM(D20:N20) -> 0
B22: TOTAL | C22: =SUM(C11:C20) -> 0 | D22: =SUM(D11:D20) -> 0 | E22: =SUM(E11:E20) -> 0 | F22: =SUM(F11:F20) -> 0 | G22: =SUM(G11:G20) -> 0 | H22: =SUM(H11:H20) -> 0 | I22: =SUM(I11:I20) -> 0 | J22: =SUM(J11:J20) -> 0 | ... O22: =SUM(O11:O20) -> 0
B24: CAPITAL
B26: Fondo Liquido | C26: =SUMIF(EneEst2024[CATEGORÍA],$B26,EneEst2024[INGRESO]) -> 0 | D26: =SUMIF(FebEst2024[CATEGORÍA],$B26,FebEst2024[INGRESO]) -> 0 | E26: =SUMIF(MarEst2024[CATEGORÍA],$B26,MarEst2024[INGRESO]) -> 0 | F26: =SUMIF(AbrEst2024[CATEGORÍA],$B26,AbrEst2024[INGRESO]) -> 0 | G26: =SUMIF(MayEst_2024[CATEGORÍA],$B26,MayEst_2024[INGRESO]) -> 0 | H26: =SUMIF(JunEst_2024[CATEGORÍA],$B26,JunEst_2024[INGRESO]) -> 0 | I26: =SUMIF(JulEst_2024[CATEGORÍA],$B26,JulEst_2024[INGRESO]) -> 0 | J26: =SUMIF(AgoEst_2024[CATEGORÍA],$B26,AgoEst_2024[INGRESO]) -> 0 | K26: =SUMIF(SepEst_2024[CATEGORÍA],$B26,SepEst_2024[INGRESO]) -> 0 | L26: =SUMIF(OctEst_2024[CATEGORÍA],$B26,OctEst_2024[INGRESO]) -> 0 | M26: =SUMIF(NovEst_2024[CATEGORÍA],$B26,NovEst_2024[INGRESO]) -> 0 | N26: =SUMIF(DicEst_2024[CATEGORÍA],$B26,DicEst_2024[INGRESO]) -> 0 | O26: =SUM(D26:N26) -> 0
B27: Capital en Inversion | C27: =C37 -> 0 | D27: =C27+D37 -> 0 | E27: =D27+E37 -> 0 | F27: =E27+F37 -> 0 | G27: =F27+G37 -> 0 | H27: =G27+H37 -> 0 | I27: =H27+I37 -> 0 | J27: =I27+J37 -> 0 | K27: =J27+K37 -> 0 | ... N27: =M27+N37 -> 0 | O27: =SUM(D27:N27) -> 0
B28: Cuentas por Cobrar | C28: =SUMIF(EneEst2024[CATEGORÍA],$B28,EneEst2024[INGRESO]) -> 0 | D28: =SUMIF(FebEst2024[CATEGORÍA],$B28,FebEst2024[INGRESO]) -> 0 | E28: =SUMIF(MarEst2024[CATEGORÍA],$B28,MarEst2024[INGRESO]) -> 0 | F28: =SUMIF(AbrEst2024[CATEGORÍA],$B28,AbrEst2024[INGRESO]) -> 0 | G28: =SUMIF(MayEst_2024[CATEGORÍA],$B28,MayEst_2024[INGRESO]) -> 0 | H28: =SUMIF(JunEst_2024[CATEGORÍA],$B28,JunEst_2024[INGRESO]) -> 0 | I28: =SUMIF(JulEst_2024[CATEGORÍA],$B28,JulEst_2024[INGRESO]) -> 0 | J28: =SUMIF(AgoEst_2024[CATEGORÍA],$B28,AgoEst_2024[INGRESO]) -> 0 | K28: =SUMIF(SepEst_2024[CATEGORÍA],$B28,SepEst_2024[INGRESO]) -> 0 | L28: =SUMIF(OctEst_2024[CATEGORÍA],$B28,OctEst_2024[INGRESO]) -> 0 | M28: =SUMIF(NovEst_2024[CATEGORÍA],$B28,NovEst_2024[INGRESO]) -> 0 | N28: =SUMIF(DicEst_2024[CATEGORÍA],$B28,DicEst_2024[INGRESO]) -> 0 | O28: =SUM(D28:N28) -> 0
B29: Otro | C29: =SUMIF(EneEst2024[CATEGORÍA],$B29,EneEst2024[INGRESO]) -> 0 | D29: =SUMIF(FebEst2024[CATEGORÍA],$B29,FebEst2024[INGRESO]) -> 0 | E29: =SUMIF(MarEst2024[CATEGORÍA],$B29,MarEst2024[INGRESO]) -> 0 | F29: =SUMIF(AbrEst2024[CATEGORÍA],$B29,AbrEst2024[INGRESO]) -> 0 | G29: =SUMIF(MayEst_2024[CATEGORÍA],$B29,MayEst_2024[INGRESO]) -> 0 | H29: =SUMIF(JunEst_2024[CATEGORÍA],$B29,JunEst_2024[INGRESO]) -> 0 | I29: =SUMIF(JulEst_2024[CATEGORÍA],$B29,JulEst_2024[INGRESO]) -> 0 | J29: =SUMIF(AgoEst_2024[CATEGORÍA],$B29,AgoEst_2024[INGRESO]) -> 0 | K29: =SUMIF(SepEst_2024[CATEGORÍA],$B29,SepEst_2024[INGRESO]) -> 0 | L29: =SUMIF(OctEst_2024[CATEGORÍA],$B29,OctEst_2024[INGRESO]) -> 0 | M29: =SUMIF(NovEst_2024[CATEGORÍA],$B29,NovEst_2024[INGRESO]) -> 0 | N29: =SUMIF(DicEst_2024[CATEGORÍA],$B29,DicEst_2024[INGRESO]) -> 0 | O29: =SUM(D29:N29) -> 0
B31: TOTAL | C31: =SUM(C26:C29) -> 0 | D31: =SUM(D26:D29) -> 0 | E31: =SUM(E26:E29) -> 0 | F31: =SUM(F26:F29) -> 0 | G31: =SUM(G26:G29) -> 0 | H31: =SUM(H26:H29) -> 0 | I31: =SUM(I26:I29) -> 0 | J31: =SUM(J26:J29) -> 0 | ... O31: =SUM(O26:O29) -> 0
B33: GASTOS OPERATIVOS
B34: RECURSOS HUMANOS
B35: Sueldos y Salarios | C35: =SUMIF(EneEst2024[CATEGORÍA],$B35,EneEst2024[EGRESO]) -> 0 | D35: =SUMIF(FebEst2024[CATEGORÍA],$B35,FebEst2024[EGRESO]) -> 0 | E35: =SUMIF(MarEst2024[CATEGORÍA],$B35,MarEst2024[EGRESO]) -> 0 | F35: =SUMIF(AbrEst2024[CATEGORÍA],$B35,AbrEst2024[EGRESO]) -> 0 | G35: =SUMIF(MayEst_2024[CATEGORÍA],$B35,MayEst_2024[EGRESO]) -> 0 | H35: =SUMIF(JunEst_2024[CATEGORÍA],$B35,JunEst_2024[EGRESO]) -> 0 | I35: =SUMIF(JulEst_2024[CATEGORÍA],$B35,JulEst_2024[EGRESO]) -> 0 | J35: =SUMIF(AgoEst_2024[CATEGORÍA],$B35,AgoEst_2024[EGRESO]) -> 0 | K35: =SUMIF(SepEst_2024[CATEGORÍA],$B35,SepEst_2024[EGRESO]) -> 0 | L35: =SUMIF(OctEst_2024[CATEGORÍA],$B35,OctEst_2024[EGRESO]) -> 0 | M35: =SUMIF(NovEst_2024[CATEGORÍA],$B35,NovEst_2024[EGRESO]) -> 0 | N35: =SUMIF(DicEst_2024[CATEGORÍA],$B35,DicEst_2024[EGRESO]) -> 0 | O35: =SUM(D35:N35) -> 0
B36: Prestamos de Nomina | C36: =SUMIF(EneEst2024[CATEGORÍA],$B36,EneEst2024[EGRESO]) -> 0 | D36: =SUMIF(FebEst2024[CATEGORÍA],$B36,FebEst2024[EGRESO]) -> 0 | E36: =SUMIF(MarEst2024[CATEGORÍA],$B36,MarEst2024[EGRESO]) -> 0 | F36: =SUMIF(AbrEst2024[CATEGORÍA],$B36,AbrEst2024[EGRESO]) -> 0 | G36: =SUMIF(MayEst_2024[CATEGORÍA],$B36,MayEst_2024[EGRESO]) -> 0 | H36: =SUMIF(JunEst_2024[CATEGORÍA],$B36,JunEst_2024[EGRESO]) -> 0 | I36: =SUMIF(JulEst_2024[CATEGORÍA],$B36,JulEst_2024[EGRESO]) -> 0 | J36: =SUMIF(AgoEst_2024[CATEGORÍA],$B36,AgoEst_2024[EGRESO]) -> 0 | K36: =SUMIF(SepEst_2024[CATEGORÍA],$B36,SepEst_2024[EGRESO]) -> 0 | L36: =SUMIF(OctEst_2024[CATEGORÍA],$B36,OctEst_2024[EGRESO]) -> 0 | M36: =SUMIF(NovEst_2024[CATEGORÍA],$B36,NovEst_2024[EGRESO]) -> 0 | N36: =SUMIF(DicEst_2024[CATEGORÍA],$B36,DicEst_2024[EGRESO]) -> 0 | O36: =SUM(D36:N36) -> 0
B37: Caja de Ahorro | C37: =SUMIF(EneEst2024[CATEGORÍA],$B37,EneEst2024[EGRESO]) -> 0 | D37: =SUMIF(FebEst2024[CATEGORÍA],$B37,FebEst2024[EGRESO]) -> 0 | E37: =SUMIF(MarEst2024[CATEGORÍA],$B37,MarEst2024[EGRESO]) -> 0 | F37: =SUMIF(AbrEst2024[CATEGORÍA],$B37,AbrEst2024[EGRESO]) -> 0 | G37: =SUMIF(MayEst_2024[CATEGORÍA],$B37,MayEst_2024[EGRESO]) -> 0 | H37: =SUMIF(JunEst_2024[CATEGORÍA],$B37,JunEst_2024[EGRESO]) -> 0 | I37: =SUMIF(JulEst_2024[CATEGORÍA],$B37,JulEst_2024[EGRESO]) -> 0 | J37: =SUMIF(AgoEst_2024[CATEGORÍA],$B37,AgoEst_2024[EGRESO]) -> 0 | K37: =SUMIF(SepEst_2024[CATEGORÍA],$B37,SepEst_2024[EGRESO]) -> 0 | L37: =SUMIF(OctEst_2024[CATEGORÍA],$B37,OctEst_2024[EGRESO]) -> 0 | M37: =SUMIF(NovEst_2024[CATEGORÍA],$B37,NovEst_2024[EGRESO]) -> 0 | N37: =SUMIF(DicEst_2024[CATEGORÍA],$B37,DicEst_2024[EGRESO]) -> 0 | O37: =SUM(D37:N37) -> 0
B38: Seguro Social | C38: =SUMIF(EneEst2024[CATEGORÍA],$B38,EneEst2024[EGRESO]) -> 0 | D38: =SUMIF(FebEst2024[CATEGORÍA],$B38,FebEst2024[EGRESO]) -> 0 | E38: =SUMIF(MarEst2024[CATEGORÍA],$B38,MarEst2024[EGRESO]) -> 0 | F38: =SUMIF(AbrEst2024[CATEGORÍA],$B38,AbrEst2024[EGRESO]) -> 0 | G38: =SUMIF(MayEst_2024[CATEGORÍA],$B38,MayEst_2024[EGRESO]) -> 0 | H38: =SUMIF(JunEst_2024[CATEGORÍA],$B38,JunEst_2024[EGRESO]) -> 0 | I38: =SUMIF(JulEst_2024[CATEGORÍA],$B38,JulEst_2024[EGRESO]) -> 0 | J38: =SUMIF(AgoEst_2024[CATEGORÍA],$B38,AgoEst_2024[EGRESO]) -> 0 | K38: =SUMIF(SepEst_2024[CATEGORÍA],$B38,SepEst_2024[EGRESO]) -> 0 | L38: =SUMIF(OctEst_2024[CATEGORÍA],$B38,OctEst_2024[EGRESO]) -> 0 | M38: =SUMIF(NovEst_2024[CATEGORÍA],$B38,NovEst_2024[EGRESO]) -> 0 | N38: =SUMIF(DicEst_2024[CATEGORÍA],$B38,DicEst_2024[EGRESO]) -> 0 | O38: =SUM(D38:N38) -> 0
B39: INFONAVIT | C39: =SUMIF(EneEst2024[CATEGORÍA],$B39,EneEst2024[EGRESO]) -> 0 | D39: =SUMIF(FebEst2024[CATEGORÍA],$B39,FebEst2024[EGRESO]) -> 0 | E39: =SUMIF(MarEst2024[CATEGORÍA],$B39,MarEst2024[EGRESO]) -> 0 | F39: =SUMIF(AbrEst2024[CATEGORÍA],$B39,AbrEst2024[EGRESO]) -> 0 | G39: =SUMIF(MayEst_2024[CATEGORÍA],$B39,MayEst_2024[EGRESO]) -> 0 | H39: =SUMIF(JunEst_2024[CATEGORÍA],$B39,JunEst_2024[EGRESO]) -> 0 | I39: =SUMIF(JulEst_2024[CATEGORÍA],$B39,JulEst_2024[EGRESO]) -> 0 | J39: =SUMIF(AgoEst_2024[CATEGORÍA],$B39,AgoEst_2024[EGRESO]) -> 0 | K39: =SUMIF(SepEst_2024[CATEGORÍA],$B39,SepEst_2024[EGRESO]) -> 0 | L39: =SUMIF(OctEst_2024[CATEGORÍA],$B39,OctEst_2024[EGRESO]) -> 0 | M39: =SUMIF(NovEst_2024[CATEGORÍA],$B39,NovEst_2024[EGRESO]) -> 0 | N39: =SUMIF(DicEst_2024[CATEGORÍA],$B39,DicEst_2024[EGRESO]) -> 0 | O39: =SUM(D39:N39) -> 0
B40: 2.5% Sobre Nomina | C40: =SUMIF(EneEst2024[CATEGORÍA],$B40,EneEst2024[EGRESO]) -> 0 | D40: =SUMIF(FebEst2024[CATEGORÍA],$B40,FebEst2024[EGRESO]) -> 0 | E40: =SUMIF(MarEst2024[CATEGORÍA],$B40,MarEst2024[EGRESO]) -> 0 | F40: =SUMIF(AbrEst2024[CATEGORÍA],$B40,AbrEst2024[EGRESO]) -> 0 | G40: =SUMIF(MayEst_2024[CATEGORÍA],$B40,MayEst_2024[EGRESO]) -> 0 | H40: =SUMIF(JunEst_2024[CATEGORÍA],$B40,JunEst_2024[EGRESO]) -> 0 | I40: =SUMIF(JulEst_2024[CATEGORÍA],$B40,JulEst_2024[EGRESO]) -> 0 | J40: =SUMIF(AgoEst_2024[CATEGORÍA],$B40,AgoEst_2024[EGRESO]) -> 0 | K40: =SUMIF(SepEst_2024[CATEGORÍA],$B40,SepEst_2024[EGRESO]) -> 0 | L40: =SUMIF(OctEst_2024[CATEGORÍA],$B40,OctEst_2024[EGRESO]) -> 0 | M40: =SUMIF(NovEst_2024[CATEGORÍA],$B40,NovEst_2024[EGRESO]) -> 0 | N40: =SUMIF(DicEst_2024[CATEGORÍA],$B40,DicEst_2024[EGRESO]) -> 0 | O40: =SUM(D40:N40) -> 0
B41: Capacitacion | C41: =SUMIF(EneEst2024[CATEGORÍA],$B41,EneEst2024[EGRESO]) -> 0 | D41: =SUMIF(FebEst2024[CATEGORÍA],$B41,FebEst2024[EGRESO]) -> 0 | E41: =SUMIF(MarEst2024[CATEGORÍA],$B41,MarEst2024[EGRESO]) -> 0 | F41: =SUMIF(AbrEst2024[CATEGORÍA],$B41,AbrEst2024[EGRESO]) -> 0 | G41: =SUMIF(MayEst_2024[CATEGORÍA],$B41,MayEst_2024[EGRESO]) -> 0 | H41: =SUMIF(JunEst_2024[CATEGORÍA],$B41,JunEst_2024[EGRESO]) -> 0 | I41: =SUMIF(JulEst_2024[CATEGORÍA],$B41,JulEst_2024[EGRESO]) -> 0 | J41: =SUMIF(AgoEst_2024[CATEGORÍA],$B41,AgoEst_2024[EGRESO]) -> 0 | K41: =SUMIF(SepEst_2024[CATEGORÍA],$B41,SepEst_2024[EGRESO]) -> 0 | L41: =SUMIF(OctEst_2024[CATEGORÍA],$B41,OctEst_2024[EGRESO]) -> 0 | M41: =SUMIF(NovEst_2024[CATEGORÍA],$B41,NovEst_2024[EGRESO]) -> 0 | N41: =SUMIF(DicEst_2024[CATEGORÍA],$B41,DicEst_2024[EGRESO]) -> 0 | O41: =SUM(D41:N41) -> 0
B42: Viaticos | C42: =SUMIF(EneEst2024[CATEGORÍA],$B42,EneEst2024[EGRESO]) -> 0 | D42: =SUMIF(FebEst2024[CATEGORÍA],$B42,FebEst2024[EGRESO]) -> 0 | E42: =SUMIF(MarEst2024[CATEGORÍA],$B42,MarEst2024[EGRESO]) -> 0 | F42: =SUMIF(AbrEst2024[CATEGORÍA],$B42,AbrEst2024[EGRESO]) -> 0 | G42: =SUMIF(MayEst_2024[CATEGORÍA],$B42,MayEst_2024[EGRESO]) -> 0 | H42: =SUMIF(JunEst_2024[CATEGORÍA],$B42,JunEst_2024[EGRESO]) -> 0 | I42: =SUMIF(JulEst_2024[CATEGORÍA],$B42,JulEst_2024[EGRESO]) -> 0 | J42: =SUMIF(AgoEst_2024[CATEGORÍA],$B42,AgoEst_2024[EGRESO]) -> 0 | K42: =SUMIF(SepEst_2024[CATEGORÍA],$B42,SepEst_2024[EGRESO]) -> 0 | L42: =SUMIF(OctEst_2024[CATEGORÍA],$B42,OctEst_2024[EGRESO]) -> 0 | M42: =SUMIF(NovEst_2024[CATEGORÍA],$B42,NovEst_2024[EGRESO]) -> 0 | N42: =SUMIF(DicEst_2024[CATEGORÍA],$B42,DicEst_2024[EGRESO]) -> 0 | O42: =SUM(D42:N42) -> 0
B43: Incentivos/Bonos | C43: =SUMIF(EneEst2024[CATEGORÍA],$B43,EneEst2024[EGRESO]) -> 0 | D43: =SUMIF(FebEst2024[CATEGORÍA],$B43,FebEst2024[EGRESO]) -> 0 | E43: =SUMIF(MarEst2024[CATEGORÍA],$B43,MarEst2024[EGRESO]) -> 0 | F43: =SUMIF(AbrEst2024[CATEGORÍA],$B43,AbrEst2024[EGRESO]) -> 0 | G43: =SUMIF(MayEst_2024[CATEGORÍA],$B43,MayEst_2024[EGRESO]) -> 0 | H43: =SUMIF(JunEst_2024[CATEGORÍA],$B43,JunEst_2024[EGRESO]) -> 0 | I43: =SUMIF(JulEst_2024[CATEGORÍA],$B43,JulEst_2024[EGRESO]) -> 0 | J43: =SUMIF(AgoEst_2024[CATEGORÍA],$B43,AgoEst_2024[EGRESO]) -> 0 | K43: =SUMIF(SepEst_2024[CATEGORÍA],$B43,SepEst_2024[EGRESO]) -> 0 | L43: =SUMIF(OctEst_2024[CATEGORÍA],$B43,OctEst_2024[EGRESO]) -> 0 | M43: =SUMIF(NovEst_2024[CATEGORÍA],$B43,NovEst_2024[EGRESO]) -> 0 | N43: =SUMIF(DicEst_2024[CATEGORÍA],$B43,DicEst_2024[EGRESO]) -> 0 | O43: =SUM(D43:N43) -> 0
B44: EPP/Uniformes | C44: =SUMIF(EneEst2024[CATEGORÍA],$B44,EneEst2024[EGRESO]) -> 0 | D44: =SUMIF(FebEst2024[CATEGORÍA],$B44,FebEst2024[EGRESO]) -> 0 | E44: =SUMIF(MarEst2024[CATEGORÍA],$B44,MarEst2024[EGRESO]) -> 0 | F44: =SUMIF(AbrEst2024[CATEGORÍA],$B44,AbrEst2024[EGRESO]) -> 0 | G44: =SUMIF(MayEst_2024[CATEGORÍA],$B44,MayEst_2024[EGRESO]) -> 0 | H44: =SUMIF(JunEst_2024[CATEGORÍA],$B44,JunEst_2024[EGRESO]) -> 0 | I44: =SUMIF(JulEst_2024[CATEGORÍA],$B44,JulEst_2024[EGRESO]) -> 0 | J44: =SUMIF(AgoEst_2024[CATEGORÍA],$B44,AgoEst_2024[EGRESO]) -> 0 | K44: =SUMIF(SepEst_2024[CATEGORÍA],$B44,SepEst_2024[EGRESO]) -> 0 | L44: =SUMIF(OctEst_2024[CATEGORÍA],$B44,OctEst_2024[EGRESO]) -> 0 | M44: =SUMIF(NovEst_2024[CATEGORÍA],$B44,NovEst_2024[EGRESO]) -> 0 | N44: =SUMIF(DicEst_2024[CATEGORÍA],$B44,DicEst_2024[EGRESO]) -> 0 | O44: =SUM(D44:N44) -> 0
B45: Liquidaciones | C45: =SUMIF(EneEst2024[CATEGORÍA],$B45,EneEst2024[EGRESO]) -> 0 | D45: =SUMIF(FebEst2024[CATEGORÍA],$B45,FebEst2024[EGRESO]) -> 0 | E45: =SUMIF(MarEst2024[CATEGORÍA],$B45,MarEst2024[EGRESO]) -> 0 | F45: =SUMIF(AbrEst2024[CATEGORÍA],$B45,AbrEst2024[EGRESO]) -> 0 | G45: =SUMIF(MayEst_2024[CATEGORÍA],$B45,MayEst_2024[EGRESO]) -> 0 | H45: =SUMIF(JunEst_2024[CATEGORÍA],$B45,JunEst_2024[EGRESO]) -> 0 | I45: =SUMIF(JulEst_2024[CATEGORÍA],$B45,JulEst_2024[EGRESO]) -> 0 | J45: =SUMIF(AgoEst_2024[CATEGORÍA],$B45,AgoEst_2024[EGRESO]) -> 0 | K45: =SUMIF(SepEst_2024[CATEGORÍA],$B45,SepEst_2024[EGRESO]) -> 0 | L45: =SUMIF(OctEst_2024[CATEGORÍA],$B45,OctEst_2024[EGRESO]) -> 0 | M45: =SUMIF(NovEst_2024[CATEGORÍA],$B45,NovEst_2024[EGRESO]) -> 0 | N45: =SUMIF(DicEst_2024[CATEGORÍA],$B45,DicEst_2024[EGRESO]) -> 0 | O45: =SUM(D45:N45) -> 0
B46: Otro RRHH | C46: =SUMIF(EneEst2024[CATEGORÍA],$B46,EneEst2024[EGRESO]) -> 0 | D46: =SUMIF(FebEst2024[CATEGORÍA],$B46,FebEst2024[EGRESO]) -> 0 | E46: =SUMIF(MarEst2024[CATEGORÍA],$B46,MarEst2024[EGRESO]) -> 0 | F46: =SUMIF(AbrEst2024[CATEGORÍA],$B46,AbrEst2024[EGRESO]) -> 0 | G46: =SUMIF(MayEst_2024[CATEGORÍA],$B46,MayEst_2024[EGRESO]) -> 0 | H46: =SUMIF(JunEst_2024[CATEGORÍA],$B46,JunEst_2024[EGRESO]) -> 0 | I46: =SUMIF(JulEst_2024[CATEGORÍA],$B46,JulEst_2024[EGRESO]) -> 0 | J46: =SUMIF(AgoEst_2024[CATEGORÍA],$B46,AgoEst_2024[EGRESO]) -> 0 | K46: =SUMIF(SepEst_2024[CATEGORÍA],$B46,SepEst_2024[EGRESO]) -> 0 | L46: =SUMIF(OctEst_2024[CATEGORÍA],$B46,OctEst_2024[EGRESO]) -> 0 | M46: =SUMIF(NovEst_2024[CATEGORÍA],$B46,NovEst_2024[EGRESO]) -> 0 | N46: =SUMIF(DicEst_2024[CATEGORÍA],$B46,DicEst_2024[EGRESO]) -> 0 | O46: =SUM(D46:N46) -> 0
C47: =SUM(C35:C46) -> 0 | D47: =SUM(D35:D46) -> 0 | E47: =SUM(E35:E46) -> 0 | F47: =SUM(F35:F46) -> 0 | G47: =SUM(G35:G46) -> 0 | H47: =SUM(H35:H46) -> 0 | I47: =SUM(I35:I46) -> 0 | J47: =SUM(J35:J46) -> 0 | ... O47: =SUM(O35:O46) -> 0
...
